Workbook

Sheet Panduan
B1: PANDUAN MENGOPERASIKAN PROGRAM DASAR PERHITUNGAN MCDM METODE AHP (Analityc Hierarchy Process)
B3: Sheet | C3: Keterangan | L3: Program MCDM metode AHP ini untuk mendukung pengambilan keputusan dari
B4: Challanges | C4: Ketik Nama Kegiatan Perhitungan AHP (disesuaikan di sini) pada sheet Challanges | L4: beberapa pilihan challenges dan didukung dengan beberapa kriteria pendukung.
C5: Input jumlah candidate challanges pada cell warna biru | L5: Perhitungan untuk mengambil keputusan melalui beberapa tahap seperti
C6: Input nama challanges dan kode challanges pada cell yang berwarna biru | L6: keterangan panduan di samping.
B7: Bobot & | C7: Input jumlah kriteria pada cell warna biru
B8: Kriteria | C8: Input nama, kode dan bobot kriteria pada cell warna biru
B9: Data Kriteria | C9: Input data nilai kriteria setiap challanges pada cell warna biru yang sesuai
C10: Kolom B adalah kode challenges otomatis tertulis (copy dari sheet Chalanges)
C11: Baris 5 adalah kode kriteria otomatis tertulis (copy dari sheet Kriteria&Bobot)
B12: Eig Vec | C12: Tampilan hasil perhitungan Eigen Vector Bobot Kriteria
B13: Bobot Kriteria | C13: Periksa CR (Consistency Ratio) dari hasil perhitungan, jika CR < 1 maka data dan hasil eigen vector
C14: sudah memenuhi syarat dan perhitungan dapat dilanjutkan, jika > 1 maka periksa data Bobot
B15: Eig Vec | C15: Tampilan hasil perhitungan Eigen Vector challenges setiap Kriteria
B16: Kriteria | C16: Periksa CR (Consistency Ratio) dari hasil perhitungan, jika CR < 1 maka data dan hasil eigen vector
C17: sudah memenuhi syarat dan perhitungan dapat dilanjutkan, jika > 1 maka periksa data Kriteria
B18: FINAL MATRIK | C18: Perkalian matrik eigen vector challenges dengan eigen vector bobot kriteria yang menghasilkan
C19: nilai untuk dapat diurutkan menjadi peringkat pada sheet PERINGKAT
B20: PERINGKAT | C20: Tampilan hasil akhir dari perhitungan AHP (Urutan Peringkat Chalanges)
C21: Apabila terjadi keanehan dalam tampilan hasil akhir, periksa CR setiap Eigen Vector Kriteria

Sheet Challanges
C1: Nama Kegiatan Perhitungan AHP (disesuaikan di sini)
B3: INPUT JUMLAH CANDIDATE CHALLENGES | E3: <=== | F3: MINIMUM 3 CHALLANGES | G3: 3 | H3: Challenges
F4: MAXIMUM 15 CHALLANGES | G4: 15 | H4: Challenges
B6: NO | C6: NAMA CHALLANGES | D6: KODE CHALLENGES | F6: Note :
B7: =IF($D$3>2,1,"") | F7: Input jumlah candidate challenges pada cell D4
B8: =IF($D$3>2,2,"") | F8: Ketik "Nama Challanges" dan "Kode Challenges" pada Cell yang warna "BIRU"
B9: =IF($D$3>2,3,"") | F9: Kode Challenges disesuaikan dengan inisial nama challenges
B10: =IF($D$3>3,4,"")
B11: =IF($D$3>4,5,"")
B12: =IF($D$3>5,6,"")
B13: =IF($D$3>6,7,"")
B14: =IF($D$3>7,8,"")
B15: =IF($D$3>8,9,"")
B16: =IF($D$3>9,10,"")
B17: =IF($D$3>10,11,"")
B18: =IF($D$3>11,12,"")
B19: =IF($D$3>12,13,"")
B20: =IF($D$3>13,14,"")
B21: =IF($D$3>14,15,"")

Sheet Kriteria&Bobot
C1: =Challanges!C1 -> Nama Kegiatan Perhitungan AHP (disesuaikan di sini)
B3: INPUT JUMLAH KRITERIA UNTUK PENENTUAN PERINGKAT | F3: <=== | G3: MINIMUM | H3: 3 | I3: Kriteria
G4: MAXIMUM | H4: 15 | I4: Kriteria
B5: No | C5: Nama Kriteria | D5: Kode Kriteria | E5: Bobot Kriteria
B6: =IF($E$3>2,1,"") | E6: =IF($E$3<1,1,"") -> 1 | G6: Note :
B7: =IF($E$3>2,2,"") | E7: =IF($E$3<2,1,"") -> 1 | G7: Input "Bobot Kriteria" minimum nilai 2 (> 1) ===> NILAI BOBOT DARI PAKAR KOMPETEN
B8: =IF($E$3>2,3,"") | E8: =IF($E$3<3,1,"") -> 1 | G8: Angka 1 (Satu) pada Cell warna Merah (kolom Bobot Kriteria) tidak boleh diubah
B9: =IF($E$3>3,4,"") | E9: =IF($E$3<4,1,"") -> 1 | G9: Ketik nama, kode, bobot kriteria pada Cell yang berwarna Biru
B10: =IF($E$3>4,5,"") | E10: =IF($E$3<5,1,"") -> 1 | G10: Ketik kode kriteria sesuai inisial kriteria
B11: =IF($E$3>5,6,"") | E11: =IF($E$3<6,1,"") -> 1
B12: =IF($E$3>6,7,"") | E12: =IF($E$3<7,1,"") -> 1
B13: =IF($E$3>7,8,"") | E13: =IF($E$3<8,1,"") -> 1
B14: =IF($E$3>8,9,"") | E14: =IF($E$3<9,1,"") -> 1
B15: =IF($E$3>9,10,"") | E15: =IF($E$3<10,1,"") -> 1
B16: =IF($E$3>10,11,"") | E16: =IF($E$3<11,1,"") -> 1
B17: =IF($E$3>11,12,"") | E17: =IF($E$3<12,1,"") -> 1
B18: =IF($E$3>12,13,"") | E18: =IF($E$3<13,1,"") -> 1
B19: =IF($E$3>13,14,"") | E19: =IF($E$3<14,1,"") -> 1
B20: =IF($E$3>14,15,"") | E20: =IF($E$3<15,1,"") -> 1

Sheet Data Kriteria
G1: DATA KRITERIA PENDUKUNG PENENTUAN PERINGKAT CHALLENGES
E2: Note : Data kriteria diisi sesuai data primer di lokasi,data sekunder dan atau keputusan pakar untuk nilai yang sesuai
B3: KRT | F3: Data kriteria diinput harus bernilai angka dan tidak boleh bernilai angka 1 (Satu) kecuali Cell warna Merah
A4: CHL | B4: ='Kriteria&Bobot'!E3 -> 0
A5: =Challanges!D3 -> 0 | C5: ='Kriteria&Bobot'!D6 -> 0 | D5: ='Kriteria&Bobot'!D7 -> 0 | E5: ='Kriteria&Bobot'!D8 -> 0 | F5: ='Eig Vec Bobot Kriteria'!F4 -> 0 | G5: ='Eig Vec Bobot Kriteria'!G4 -> 0 | H5: ='Eig Vec Bobot Kriteria'!H4 -> 0 | I5: ='Eig Vec Bobot Kriteria'!I4 -> 0 | J5: ='Eig Vec Bobot Kriteria'!J4 -> 0 | K5: ='Eig Vec Bobot Kriteria'!K4 -> 0 | L5: ='Eig Vec Bobot Kriteria'!L4 -> 0 | M5: ='Eig Vec Bobot Kriteria'!M4 -> 0 | ... Q5: ='Eig Vec Bobot Kriteria'!Q4 -> 0
B6: =Challanges!D7 -> 0 | C6: =IF(AND($A$5>2,$B$4>2),"",1) -> 1 | D6: =IF(AND($A$5>2,$B$4>2),"",1) -> 1 | E6: =IF(AND($A$5>2,$B$4>2),"",1) -> 1 | F6: =IF(AND($A$5>2,$B$4>3),"",1) -> 1 | G6: =IF(AND($A$5>2,$B$4>4),"",1) -> 1 | H6: =IF(AND($A$5>2,$B$4>5),"",1) -> 1 | I6: =IF(AND($A$5>2,$B$4>6),"",1) -> 1 | J6: =IF(AND($A$5>2,$B$4>7),"",1) -> 1 | K6: =IF(AND($A$5>2,$B$4>8),"",1) -> 1 | L6: =IF(AND($A$5>2,$B$4>9),"",1) -> 1 | M6: =IF(AND($A$5>2,$B$4>10),"",1) -> 1 | N6: =IF(AND($A$5>2,$B$4>11),"",1) -> 1 | O6: =IF(AND($A$5>2,$B$4>12),"",1) -> 1 | P6: =IF(AND($A$5>2,$B$4>13),"",1) -> 1 | Q6: =IF(AND($A$5>2,$B$4>14),"",1) -> 1
B7: =Challanges!D8 -> 0 | C7: =IF(AND($A$5>2,$B$4>2),"",1) -> 1 | D7: =IF(AND($A$5>2,$B$4>2),"",1) -> 1 | E7: =IF(AND($A$5>2,$B$4>2),"",1) -> 1 | F7: =IF(AND($A$5>2,$B$4>3),"",1) -> 1 | G7: =IF(AND($A$5>2,$B$4>4),"",1) -> 1 | H7: =IF(AND($A$5>2,$B$4>5),"",1) -> 1 | I7: =IF(AND($A$5>2,$B$4>6),"",1) -> 1 | J7: =IF(AND($A$5>2,$B$4>7),"",1) -> 1 | K7: =IF(AND($A$5>2,$B$4>8),"",1) -> 1 | L7: =IF(AND($A$5>2,$B$4>9),"",1) -> 1 | M7: =IF(AND($A$5>2,$B$4>10),"",1) -> 1 | N7: =IF(AND($A$5>2,$B$4>11),"",1) -> 1 | O7: =IF(AND($A$5>2,$B$4>12),"",1) -> 1 | P7: =IF(AND($A$5>2,$B$4>13),"",1) -> 1 | Q7: =IF(AND($A$5>2,$B$4>14),"",1) -> 1
B8: =Challanges!D9 -> 0 | C8: =IF(AND($A$5>2,$B$4>2),"",1) -> 1 | D8: =IF(AND($A$5>2,$B$4>2),"",1) -> 1 | E8: =IF(AND($A$5>2,$B$4>2),"",1) -> 1 | F8: =IF(AND($A$5>2,$B$4>3),"",1) -> 1 | G8: =IF(AND($A$5>2,$B$4>4),"",1) -> 1 | H8: =IF(AND($A$5>2,$B$4>5),"",1) -> 1 | I8: =IF(AND($A$5>2,$B$4>6),"",1) -> 1 | J8: =IF(AND($A$5>2,$B$4>7),"",1) -> 1 | K8: =IF(AND($A$5>2,$B$4>8),"",1) -> 1 | L8: =IF(AND($A$5>2,$B$4>9),"",1) -> 1 | M8: =IF(AND($A$5>2,$B$4>10),"",1) -> 1 | N8: =IF(AND($A$5>2,$B$4>11),"",1) -> 1 | O8: =IF(AND($A$5>2,$B$4>12),"",1) -> 1 | P8: =IF(AND($A$5>2,$B$4>13),"",1) -> 1 | Q8: =IF(AND($A$5>2,$B$4>14),"",1) -> 1
B9: =Challanges!D10 -> 0 | C9: =IF(AND($A$5>3,$B$4>2),"",1) -> 1 | D9: =IF(AND($A$5>3,$B$4>2),"",1) -> 1 | E9: =IF(AND($A$5>3,$B$4>2),"",1) -> 1 | F9: =IF(AND($A$5>3,$B$4>3),"",1) -> 1 | G9: =IF(AND($A$5>3,$B$4>4),"",1) -> 1 | H9: =IF(AND($A$5>3,$B$4>5),"",1) -> 1 | I9: =IF(AND($A$5>3,$B$4>6),"",1) -> 1 | J9: =IF(AND($A$5>3,$B$4>7),"",1) -> 1 | K9: =IF(AND($A$5>3,$B$4>8),"",1) -> 1 | L9: =IF(AND($A$5>3,$B$4>9),"",1) -> 1 | M9: =IF(AND($A$5>3,$B$4>10),"",1) -> 1 | N9: =IF(AND($A$5>3,$B$4>11),"",1) -> 1 | O9: =IF(AND($A$5>3,$B$4>12),"",1) -> 1 | P9: =IF(AND($A$5>3,$B$4>13),"",1) -> 1 | Q9: =IF(AND($A$5>3,$B$4>14),"",1) -> 1
B10: =Challanges!D11 -> 0 | C10: =IF(AND($A$5>4,$B$4>2),"",1) -> 1 | D10: =IF(AND($A$5>4,$B$4>2),"",1) -> 1 | E10: =IF(AND($A$5>4,$B$4>2),"",1) -> 1 | F10: =IF(AND($A$5>4,$B$4>3),"",1) -> 1 | G10: =IF(AND($A$5>4,$B$4>4),"",1) -> 1 | H10: =IF(AND($A$5>4,$B$4>5),"",1) -> 1 | I10: =IF(AND($A$5>4,$B$4>6),"",1) -> 1 | J10: =IF(AND($A$5>4,$B$4>7),"",1) -> 1 | K10: =IF(AND($A$5>4,$B$4>8),"",1) -> 1 | L10: =IF(AND($A$5>4,$B$4>9),"",1) -> 1 | M10: =IF(AND($A$5>4,$B$4>10),"",1) -> 1 | N10: =IF(AND($A$5>4,$B$4>11),"",1) -> 1 | O10: =IF(AND($A$5>4,$B$4>12),"",1) -> 1 | P10: =IF(AND($A$5>4,$B$4>13),"",1) -> 1 | Q10: =IF(AND($A$5>4,$B$4>14),"",1) -> 1
B11: =Challanges!D12 -> 0 | C11: =IF(AND($A$5>5,$B$4>2),"",1) -> 1 | D11: =IF(AND($A$5>5,$B$4>2),"",1) -> 1 | E11: =IF(AND($A$5>5,$B$4>2),"",1) -> 1 | F11: =IF(AND($A$5>5,$B$4>3),"",1) -> 1 | G11: =IF(AND($A$5>5,$B$4>4),"",1) -> 1 | H11: =IF(AND($A$5>4,$B$4>5),"",1) -> 1 | I11: =IF(AND($A$5>5,$B$4>6),"",1) -> 1 | J11: =IF(AND($A$5>5,$B$4>7),"",1) -> 1 | K11: =IF(AND($A$5>5,$B$4>8),"",1) -> 1 | L11: =IF(AND($A$5>5,$B$4>9),"",1) -> 1 | M11: =IF(AND($A$5>5,$B$4>10),"",1) -> 1 | N11: =IF(AND($A$5>5,$B$4>11),"",1) -> 1 | O11: =IF(AND($A$5>5,$B$4>12),"",1) -> 1 | P11: =IF(AND($A$5>5,$B$4>13),"",1) -> 1 | Q11: =IF(AND($A$5>5,$B$4>14),"",1) -> 1
B12: =Challanges!D13 -> 0 | C12: =IF(AND($A$5>6,$B$4>2),"",1) -> 1 | D12: =IF(AND($A$5>6,$B$4>2),"",1) -> 1 | E12: =IF(AND($A$5>6,$B$4>2),"",1) -> 1 | F12: =IF(AND($A$5>6,$B$4>3),"",1) -> 1 | G12: =IF(AND($A$5>6,$B$4>4),"",1) -> 1 | H12: =IF(AND($A$5>6,$B$4>5),"",1) -> 1 | I12: =IF(AND($A$5>6,$B$4>6),"",1) -> 1 | J12: =IF(AND($A$5>6,$B$4>7),"",1) -> 1 | K12: =IF(AND($A$5>6,$B$4>8),"",1) -> 1 | L12: =IF(AND($A$5>6,$B$4>9),"",1) -> 1 | M12: =IF(AND($A$5>6,$B$4>10),"",1) -> 1 | N12: =IF(AND($A$5>6,$B$4>11),"",1) -> 1 | O12: =IF(AND($A$5>6,$B$4>12),"",1) -> 1 | P12: =IF(AND($A$5>6,$B$4>13),"",1) -> 1 | Q12: =IF(AND($A$5>6,$B$4>14),"",1) -> 1
B13: =Challanges!D14 -> 0 | C13: =IF(AND($A$5>7,$B$4>2),"",1) -> 1 | D13: =IF(AND($A$5>7,$B$4>2),"",1) -> 1 | E13: =IF(AND($A$5>7,$B$4>2),"",1) -> 1 | F13: =IF(AND($A$5>7,$B$4>3),"",1) -> 1 | G13: =IF(AND($A$5>7,$B$4>4),"",1) -> 1 | H13: =IF(AND($A$5>7,$B$4>5),"",1) -> 1 | I13: =IF(AND($A$5>7,$B$4>6),"",1) -> 1 | J13: =IF(AND($A$5>7,$B$4>7),"",1) -> 1 | K13: =IF(AND($A$5>7,$B$4>8),"",1) -> 1 | L13: =IF(AND($A$5>7,$B$4>9),"",1) -> 1 | M13: =IF(AND($A$5>7,$B$4>10),"",1) -> 1 | N13: =IF(AND($A$5>7,$B$4>11),"",1) -> 1 | O13: =IF(AND($A$5>7,$B$4>12),"",1) -> 1 | P13: =IF(AND($A$5>7,$B$4>13),"",1) -> 1 | Q13: =IF(AND($A$5>7,$B$4>14),"",1) -> 1
B14: =Challanges!D15 -> 0 | C14: =IF(AND($A$5>8,$B$4>2),"",1) -> 1 | D14: =IF(AND($A$5>8,$B$4>2),"",1) -> 1 | E14: =IF(AND($A$5>8,$B$4>2),"",1) -> 1 | F14: =IF(AND($A$5>8,$B$4>3),"",1) -> 1 | G14: =IF(AND($A$5>8,$B$4>4),"",1) -> 1 | H14: =IF(AND($A$5>8,$B$4>5),"",1) -> 1 | I14: =IF(AND($A$5>8,$B$4>6),"",1) -> 1 | J14: =IF(AND($A$5>8,$B$4>7),"",1) -> 1 | K14: =IF(AND($A$5>8,$B$4>8),"",1) -> 1 | L14: =IF(AND($A$5>8,$B$4>9),"",1) -> 1 | M14: =IF(AND($A$5>8,$B$4>10),"",1) -> 1 | N14: =IF(AND($A$5>8,$B$4>11),"",1) -> 1 | O14: =IF(AND($A$5>8,$B$4>12),"",1) -> 1 | P14: =IF(AND($A$5>8,$B$4>13),"",1) -> 1 | Q14: =IF(AND($A$5>8,$B$4>14),"",1) -> 1
B15: =Challanges!D16 -> 0 | C15: =IF(AND($A$5>9,$B$4>2),"",1) -> 1 | D15: =IF(AND($A$5>9,$B$4>2),"",1) -> 1 | E15: =IF(AND($A$5>9,$B$4>2),"",1) -> 1 | F15: =IF(AND($A$5>9,$B$4>3),"",1) -> 1 | G15: =IF(AND($A$5>9,$B$4>4),"",1) -> 1 | H15: =IF(AND($A$5>9,$B$4>5),"",1) -> 1 | I15: =IF(AND($A$5>9,$B$4>6),"",1) -> 1 | J15: =IF(AND($A$5>9,$B$4>7),"",1) -> 1 | K15: =IF(AND($A$5>9,$B$4>8),"",1) -> 1 | L15: =IF(AND($A$5>9,$B$4>9),"",1) -> 1 | M15: =IF(AND($A$5>9,$B$4>10),"",1) -> 1 | N15: =IF(AND($A$5>9,$B$4>11),"",1) -> 1 | O15: =IF(AND($A$5>9,$B$4>12),"",1) -> 1 | P15: =IF(AND($A$5>9,$B$4>13),"",1) -> 1 | Q15: =IF(AND($A$5>9,$B$4>14),"",1) -> 1
B16: =Challanges!D17 -> 0 | C16: =IF(AND($A$5>10,$B$4>2),"",1) -> 1 | D16: =IF(AND($A$5>10,$B$4>2),"",1) -> 1 | E16: =IF(AND($A$5>10,$B$4>2),"",1) -> 1 | F16: =IF(AND($A$5>10,$B$4>3),"",1) -> 1 | G16: =IF(AND($A$5>10,$B$4>4),"",1) -> 1 | H16: =IF(AND($A$5>10,$B$4>5),"",1) -> 1 | I16: =IF(AND($A$5>10,$B$4>6),"",1) -> 1 | J16: =IF(AND($A$5>10,$B$4>7),"",1) -> 1 | K16: =IF(AND($A$5>10,$B$4>8),"",1) -> 1 | L16: =IF(AND($A$5>10,$B$4>9),"",1) -> 1 | M16: =IF(AND($A$5>10,$B$4>10),"",1) -> 1 | N16: =IF(AND($A$5>10,$B$4>11),"",1) -> 1 | O16: =IF(AND($A$5>10,$B$4>12),"",1) -> 1 | P16: =IF(AND($A$5>10,$B$4>13),"",1) -> 1 | Q16: =IF(AND($A$5>10,$B$4>14),"",1) -> 1
B17: =Challanges!D18 -> 0 | C17: =IF(AND($A$5>11,$B$4>2),"",1) -> 1 | D17: =IF(AND($A$5>11,$B$4>2),"",1) -> 1 | E17: =IF(AND($A$5>11,$B$4>2),"",1) -> 1 | F17: =IF(AND($A$5>11,$B$4>3),"",1) -> 1 | G17: =IF(AND($A$5>11,$B$4>4),"",1) -> 1 | H17: =IF(AND($A$5>11,$B$4>5),"",1) -> 1 | I17: =IF(AND($A$5>11,$B$4>6),"",1) -> 1 | J17: =IF(AND($A$5>11,$B$4>7),"",1) -> 1 | K17: =IF(AND($A$5>11,$B$4>8),"",1) -> 1 | L17: =IF(AND($A$5>11,$B$4>9),"",1) -> 1 | M17: =IF(AND($A$5>11,$B$4>10),"",1) -> 1 | N17: =IF(AND($A$5>11,$B$4>11),"",1) -> 1 | O17: =IF(AND($A$5>11,$B$4>12),"",1) -> 1 | P17: =IF(AND($A$5>11,$B$4>13),"",1) -> 1 | Q17: =IF(AND($A$5>11,$B$4>14),"",1) -> 1
B18: =Challanges!D19 -> 0 | C18: =IF(AND($A$5>12,$B$4>2),"",1) -> 1 | D18: =IF(AND($A$5>12,$B$4>2),"",1) -> 1 | E18: =IF(AND($A$5>12,$B$4>2),"",1) -> 1 | F18: =IF(AND($A$5>12,$B$4>3),"",1) -> 1 | G18: =IF(AND($A$5>12,$B$4>4),"",1) -> 1 | H18: =IF(AND($A$5>12,$B$4>5),"",1) -> 1 | I18: =IF(AND($A$5>12,$B$4>6),"",1) -> 1 | J18: =IF(AND($A$5>12,$B$4>7),"",1) -> 1 | K18: =IF(AND($A$5>12,$B$4>8),"",1) -> 1 | L18: =IF(AND($A$5>12,$B$4>9),"",1) -> 1 | M18: =IF(AND($A$5>12,$B$4>10),"",1) -> 1 | N18: =IF(AND($A$5>12,$B$4>11),"",1) -> 1 | O18: =IF(AND($A$5>12,$B$4>12),"",1) -> 1 | P18: =IF(AND($A$5>12,$B$4>13),"",1) -> 1 | Q18: =IF(AND($A$5>12,$B$4>14),"",1) -> 1
B19: =Challanges!D20 -> 0 | C19: =IF(AND($A$5>13,$B$4>2),"",1) -> 1 | D19: =IF(AND($A$5>13,$B$4>2),"",1) -> 1 | E19: =IF(AND($A$5>13,$B$4>2),"",1) -> 1 | F19: =IF(AND($A$5>13,$B$4>3),"",1) -> 1 | G19: =IF(AND($A$5>13,$B$4>4),"",1) -> 1 | H19: =IF(AND($A$5>13,$B$4>5),"",1) -> 1 | I19: =IF(AND($A$5>13,$B$4>6),"",1) -> 1 | J19: =IF(AND($A$5>13,$B$4>7),"",1) -> 1 | K19: =IF(AND($A$5>13,$B$4>8),"",1) -> 1 | L19: =IF(AND($A$5>13,$B$4>9),"",1) -> 1 | M19: =IF(AND($A$5>13,$B$4>10),"",1) -> 1 | N19: =IF(AND($A$5>13,$B$4>11),"",1) -> 1 | O19: =IF(AND($A$5>13,$B$4>12),"",1) -> 1 | P19: =IF(AND($A$5>13,$B$4>13),"",1) -> 1 | Q19: =IF(AND($A$5>13,$B$4>14),"",1) -> 1
B20: =Challanges!D21 -> 0 | C20: =IF(AND($A$5>14,$B$4>2),"",1) -> 1 | D20: =IF(AND($A$5>14,$B$4>2),"",1) -> 1 | E20: =IF(AND($A$5>14,$B$4>2),"",1) -> 1 | F20: =IF(AND($A$5>14,$B$4>3),"",1) -> 1 | G20: =IF(AND($A$5>14,$B$4>4),"",1) -> 1 | H20: =IF(AND($A$5>14,$B$4>5),"",1) -> 1 | I20: =IF(AND($A$5>14,$B$4>6),"",1) -> 1 | J20: =IF(AND($A$5>14,$B$4>7),"",1) -> 1 | K20: =IF(AND($A$5>14,$B$4>8),"",1) -> 1 | L20: =IF(AND($A$5>14,$B$4>9),"",1) -> 1 | M20: =IF(AND($A$5>14,$B$4>10),"",1) -> 1 | N20: =IF(AND($A$5>14,$B$4>11),"",1) -> 1 | O20: =IF(AND($A$5>14,$B$4>12),"",1) -> 1 | P20: =IF(AND($A$5>14,$B$4>13),"",1) -> 1 | Q20: =IF(AND($A$5>14,$B$4>14),"",1) -> 1

Sheet Eig Vec Bobot Kriteria
B1: MATRIK BOBOT KRITERIA
C3: {=TRANSPOSE('Kriteria&Bobot'!E6:E20)} -> 1 | D3: 1 | E3: 1 | F3: 1 | G3: 1 | H3: 1 | I3: 1 | J3: 1 | K3: 1 | L3: 1 | M3: 1 | N3: 1 | O3: 1 | P3: 1 | Q3: 1
B4: ### | C4: {=TRANSPOSE('Kriteria&Bobot'!D6:D20)} -> 0 | D4: 0 | E4: 0 | F4: 0 | G4: 0 | H4: 0 | I4: 0 | J4: 0 | K4: 0 | L4: 0 | M4: 0 | N4: 0 | O4: 0 | P4: 0 | Q4: 0 | R4: nth root | S4: Eigenvector | T4: Eigenvelue
A5: ='Kriteria&Bobot'!E6 -> 1 | B5: ='Kriteria&Bobot'!D6 -> 0 | C5: =IF(OR(C3=1,$A$5=1),1,$A$5/C3) -> 1 | D5: =IF(OR(D3=1,$A$5=1),1,$A$5/D3) -> 1 | E5: =IF(OR(E3=1,$A$5=1),1,$A$5/E3) -> 1 | F5: =IF(OR(F3=1,$A$5=1),1,$A$5/F3) -> 1 | G5: =IF(OR(G3=1,$A$5=1),1,$A$5/G3) -> 1 | H5: =IF(OR(H3=1,$A$5=1),1,$A$5/H3) -> 1 | I5: =IF(OR(I3=1,$A$5=1),1,$A$5/I3) -> 1 | J5: =IF(OR(J3=1,$A$5=1),1,$A$5/J3) -> 1 | ... Q5: =IF(OR(Q3=1,$A$5=1),1,$A$5/Q3) -> 1 | R5: =IF(A5=1,0,(C5*D5*E5*F5*G5*H5*I5*J5*K5*L5*M5*N5*O5*P5*Q5)^(1/'Kriteria&Bobot'!$E$3)) -> 0 | S5: =R5/$R$20 -> #DIV/0! | T5: =IF(A5=1,0,(C5*$S$5+D5*$S$6+E5*$S$7+F5*$S$8+G5*$S$9+H5*$S$10+I5*$S$11+J5*$S$12+K5*$S$13+L5*$S$14+M5*$S$15+N5*$S$16+O5*$S$17+P5*$S$18+Q5*$S$19)/S5) -> 0
A6: ='Kriteria&Bobot'!E7 -> 1 | B6: ='Kriteria&Bobot'!D7 -> 0 | C6: =IF(OR(C3=1,$A$6=1),1,$A$6/C3) -> 1 | D6: =IF(OR(D3=1,$A$6=1),1,$A$6/D3) -> 1 | E6: =IF(OR(E3=1,$A$6=1),1,$A$6/E3) -> 1 | F6: =IF(OR(F3=1,$A$6=1),1,$A$6/F3) -> 1 | G6: =IF(OR(G3=1,$A$6=1),1,$A$6/G3) -> 1 | H6: =IF(OR(H3=1,$A$6=1),1,$A$6/H3) -> 1 | I6: =IF(OR(I3=1,$A$6=1),1,$A$6/I3) -> 1 | J6: =IF(OR(J3=1,$A$6=1),1,$A$6/J3) -> 1 | ... Q6: =IF(OR(Q3=1,$A$6=1),1,$A$6/Q3) -> 1 | R6: =IF(A6=1,0,(C6*D6*E6*F6*G6*H6*I6*J6*K6*L6*M6*N6*O6*P6*Q6)^(1/'Kriteria&Bobot'!$E$3)) -> 0 | S6: =R6/$R$20 -> #DIV/0! | T6: =IF(A6=1,0,(C6*$S$5+D6*$S$6+E6*$S$7+F6*$S$8+G6*$S$9+H6*$S$10+I6*$S$11+J6*$S$12+K6*$S$13+L6*$S$14+M6*$S$15+N6*$S$16+O6*$S$17+P6*$S$18+Q6*$S$19)/S6) -> 0
A7: ='Kriteria&Bobot'!E8 -> 1 | B7: ='Kriteria&Bobot'!D8 -> 0 | C7: =IF(OR(C3=1,$A$7=1),1,$A$7/C3) -> 1 | D7: =IF(OR(D3=1,$A$7=1),1,$A$7/D3) -> 1 | E7: =IF(OR(E3=1,$A$7=1),1,$A$7/E3) -> 1 | F7: =IF(OR(F3=1,$A$7=1),1,$A$7/F3) -> 1 | G7: =IF(OR(G3=1,$A$7=1),1,$A$7/G3) -> 1 | H7: =IF(OR(H3=1,$A$7=1),1,$A$7/H3) -> 1 | I7: =IF(OR(I3=1,$A$7=1),1,$A$7/I3) -> 1 | J7: =IF(OR(J3=1,$A$7=1),1,$A$7/J3) -> 1 | ... Q7: =IF(OR(Q3=1,$A$7=1),1,$A$7/Q3) -> 1 | R7: =IF(A7=1,0,(C7*D7*E7*F7*G7*H7*I7*J7*K7*L7*M7*N7*O7*P7*Q7)^(1/'Kriteria&Bobot'!$E$3)) -> 0 | S7: =R7/$R$20 -> #DIV/0! | T7: =IF(A7=1,0,(C7*$S$5+D7*$S$6+E7*$S$7+F7*$S$8+G7*$S$9+H7*$S$10+I7*$S$11+J7*$S$12+K7*$S$13+L7*$S$14+M7*$S$15+N7*$S$16+O7*$S$17+P7*$S$18+Q7*$S$19)/S7) -> 0
A8: ='Kriteria&Bobot'!E9 -> 1 | B8: ='Kriteria&Bobot'!D9 -> 0 | C8: =IF(OR(C3=1,$A$8=1),1,$A$8/C3) -> 1 | D8: =IF(OR(D3=1,$A$8=1),1,$A$8/D3) -> 1 | E8: =IF(OR(E3=1,$A$8=1),1,$A$8/E3) -> 1 | F8: =IF(OR(F3=1,$A$8=1),1,$A$8/F3) -> 1 | G8: =IF(OR(G3=1,$A$8=1),1,$A$8/G3) -> 1 | H8: =IF(OR(H3=1,$A$8=1),1,$A$8/H3) -> 1 | I8: =IF(OR(I3=1,$A$8=1),1,$A$8/I3) -> 1 | J8: =IF(OR(J3=1,$A$8=1),1,$A$8/J3) -> 1 | ... Q8: =IF(OR(Q3=1,$A$8=1),1,$A$8/Q3) -> 1 | R8: =IF(A8=1,0,(C8*D8*E8*F8*G8*H8*I8*J8*K8*L8*M8*N8*O8*P8*Q8)^(1/'Kriteria&Bobot'!$E$3)) -> 0 | S8: =R8/$R$20 -> #DIV/0! | T8: =IF(A8=1,0,(C8*$S$5+D8*$S$6+E8*$S$7+F8*$S$8+G8*$S$9+H8*$S$10+I8*$S$11+J8*$S$12+K8*$S$13+L8*$S$14+M8*$S$15+N8*$S$16+O8*$S$17+P8*$S$18+Q8*$S$19)/S8) -> 0
A9: ='Kriteria&Bobot'!E10 -> 1 | B9: ='Kriteria&Bobot'!D10 -> 0 | C9: =IF(OR(C3=1,$A$9=1),1,$A$9/C3) -> 1 | D9: =IF(OR(D3=1,$A$9=1),1,$A$9/D3) -> 1 | E9: =IF(OR(E3=1,$A$9=1),1,$A$9/E3) -> 1 | F9: =IF(OR(F3=1,$A$9=1),1,$A$9/F3) -> 1 | G9: =IF(OR(G3=1,$A$9=1),1,$A$9/G3) -> 1 | H9: =IF(OR(H3=1,$A$9=1),1,$A$9/H3) -> 1 | I9: =IF(OR(I3=1,$A$9=1),1,$A$9/I3) -> 1 | J9: =IF(OR(J3=1,$A$9=1),1,$A$9/J3) -> 1 | ... Q9: =IF(OR(Q3=1,$A$9=1),1,$A$9/Q3) -> 1 | R9: =IF(A9=1,0,(C9*D9*E9*F9*G9*H9*I9*J9*K9*L9*M9*N9*O9*P9*Q9)^(1/'Kriteria&Bobot'!$E$3)) -> 0 | S9: =R9/$R$20 -> #DIV/0! | T9: =IF(A9=1,0,(C9*$S$5+D9*$S$6+E9*$S$7+F9*$S$8+G9*$S$9+H9*$S$10+I9*$S$11+J9*$S$12+K9*$S$13+L9*$S$14+M9*$S$15+N9*$S$16+O9*$S$17+P9*$S$18+Q9*$S$19)/S9) -> 0
A10: ='Kriteria&Bobot'!E11 -> 1 | B10: ='Kriteria&Bobot'!D11 -> 0 | C10: =IF(OR(C3=1,$A$10=1),1,$A$10/C3) -> 1 | D10: =IF(OR(D3=1,$A$10=1),1,$A$10/D3) -> 1 | E10: =IF(OR(E3=1,$A$10=1),1,$A$10/E3) -> 1 | F10: =IF(OR(F3=1,$A$10=1),1,$A$10/F3) -> 1 | G10: =IF(OR(G3=1,$A$10=1),1,$A$10/G3) -> 1 | H10: =IF(OR(H3=1,$A$10=1),1,$A$10/H3) -> 1 | I10: =IF(OR(I3=1,$A$10=1),1,$A$10/I3) -> 1 | J10: =IF(OR(J3=1,$A$10=1),1,$A$10/J3) -> 1 | ... Q10: =IF(OR(Q3=1,$A$10=1),1,$A$10/Q3) -> 1 | R10: =IF(A10=1,0,(C10*D10*E10*F10*G10*H10*I10*J10*K10*L10*M10*N10*O10*P10*Q10)^(1/'Kriteria&Bobot'!$E$3)) -> 0 | S10: =R10/$R$20 -> #DIV/0! | T10: =IF(A10=1,0,(C10*$S$5+D10*$S$6+E10*$S$7+F10*$S$8+G10*$S$9+H10*$S$10+I10*$S$11+J10*$S$12+K10*$S$13+L10*$S$14+M10*$S$15+N10*$S$16+O10*$S$17+P10*$S$18+Q10*$S$19)/S10) -> 0
A11: ='Kriteria&Bobot'!E12 -> 1 | B11: ='Kriteria&Bobot'!D12 -> 0 | C11: =IF(OR(C3=1,$A$11=1),1,$A$11/C3) -> 1 | D11: =IF(OR(D3=1,$A$11=1),1,$A$11/D3) -> 1 | E11: =IF(OR(E3=1,$A$11=1),1,$A$11/E3) -> 1 | F11: =IF(OR(F3=1,$A$11=1),1,$A$11/F3) -> 1 | G11: =IF(OR(G3=1,$A$11=1),1,$A$11/G3) -> 1 | H11: =IF(OR(H3=1,$A$11=1),1,$A$11/H3) -> 1 | I11: =IF(OR(I3=1,$A$11=1),1,$A$11/I3) -> 1 | J11: =IF(OR(J3=1,$A$11=1),1,$A$11/J3) -> 1 | ... Q11: =IF(OR(Q3=1,$A$11=1),1,$A$11/Q3) -> 1 | R11: =IF(A11=1,0,(C11*D11*E11*F11*G11*H11*I11*J11*K11*L11*M11*N11*O11*P11*Q11)^(1/'Kriteria&Bobot'!$E$3)) -> 0 | S11: =R11/$R$20 -> #DIV/0! | T11: =IF(A11=1,0,(C11*$S$5+D11*$S$6+E11*$S$7+F11*$S$8+G11*$S$9+H11*$S$10+I11*$S$11+J11*$S$12+K11*$S$13+L11*$S$14+M11*$S$15+N11*$S$16+O11*$S$17+P11*$S$18+Q11*$S$19)/S11) -> 0
A12: ='Kriteria&Bobot'!E13 -> 1 | B12: ='Kriteria&Bobot'!D13 -> 0 | C12: =IF(OR(C3=1,$A$12=1),1,$A$12/C3) -> 1 | D12: =IF(OR(D3=1,$A$12=1),1,$A$12/D3) -> 1 | E12: =IF(OR(E3=1,$A$12=1),1,$A$12/E3) -> 1 | F12: =IF(OR(F3=1,$A$12=1),1,$A$12/F3) -> 1 | G12: =IF(OR(G3=1,$A$12=1),1,$A$12/G3) -> 1 | H12: =IF(OR(H3=1,$A$12=1),1,$A$12/H3) -> 1 | I12: =IF(OR(I3=1,$A$12=1),1,$A$12/I3) -> 1 | J12: =IF(OR(J3=1,$A$12=1),1,$A$12/J3) -> 1 | ... Q12: =IF(OR(Q3=1,$A$12=1),1,$A$12/Q3) -> 1 | R12: =IF(A12=1,0,(C12*D12*E12*F12*G12*H12*I12*J12*K12*L12*M12*N12*O12*P12*Q12)^(1/'Kriteria&Bobot'!$E$3)) -> 0 | S12: =R12/$R$20 -> #DIV/0! | T12: =IF(A12=1,0,(C12*$S$5+D12*$S$6+E12*$S$7+F12*$S$8+G12*$S$9+H12*$S$10+I12*$S$11+J12*$S$12+K12*$S$13+L12*$S$14+M12*$S$15+N12*$S$16+O12*$S$17+P12*$S$18+Q12*$S$19)/S12) -> 0
A13: ='Kriteria&Bobot'!E14 -> 1 | B13: ='Kriteria&Bobot'!D14 -> 0 | C13: =IF(OR(C3=1,$A$13=1),1,$A$13/C3) -> 1 | D13: =IF(OR(D3=1,$A$13=1),1,$A$13/D3) -> 1 | E13: =IF(OR(E3=1,$A$13=1),1,$A$13/E3) -> 1 | F13: =IF(OR(F3=1,$A$13=1),1,$A$13/F3) -> 1 | G13: =IF(OR(G3=1,$A$13=1),1,$A$13/G3) -> 1 | H13: =IF(OR(H3=1,$A$13=1),1,$A$13/H3) -> 1 | I13: =IF(OR(I3=1,$A$13=1),1,$A$13/I3) -> 1 | J13: =IF(OR(J3=1,$A$13=1),1,$A$13/J3) -> 1 | ... Q13: =IF(OR(Q3=1,$A$13=1),1,$A$13/Q3) -> 1 | R13: =IF(A13=1,0,(C13*D13*E13*F13*G13*H13*I13*J13*K13*L13*M13*N13*O13*P13*Q13)^(1/'Kriteria&Bobot'!$E$3)) -> 0 | S13: =R13/$R$20 -> #DIV/0! | T13: =IF(A13=1,0,(C13*$S$5+D13*$S$6+E13*$S$7+F13*$S$8+G13*$S$9+H13*$S$10+I13*$S$11+J13*$S$12+K13*$S$13+L13*$S$14+M13*$S$15+N13*$S$16+O13*$S$17+P13*$S$18+Q13*$S$19)/S13) -> 0
A14: ='Kriteria&Bobot'!E15 -> 1 | B14: ='Kriteria&Bobot'!D15 -> 0 | C14: =IF(OR(C3=1,$A$14=1),1,$A$14/C3) -> 1 | D14: =IF(OR(D3=1,$A$14=1),1,$A$14/D3) -> 1 | E14: =IF(OR(E3=1,$A$14=1),1,$A$14/E3) -> 1 | F14: =IF(OR(F3=1,$A$14=1),1,$A$14/F3) -> 1 | G14: =IF(OR(G3=1,$A$14=1),1,$A$14/G3) -> 1 | H14: =IF(OR(H3=1,$A$14=1),1,$A$14/H3) -> 1 | I14: =IF(OR(I3=1,$A$14=1),1,$A$14/I3) -> 1 | J14: =IF(OR(J3=1,$A$14=1),1,$A$14/J3) -> 1 | ... Q14: =IF(OR(Q3=1,$A$14=1),1,$A$14/Q3) -> 1 | R14: =IF(A14=1,0,(C14*D14*E14*F14*G14*H14*I14*J14*K14*L14*M14*N14*O14*P14*Q14)^(1/'Kriteria&Bobot'!$E$3)) -> 0 | S14: =R14/$R$20 -> #DIV/0! | T14: =IF(A14=1,0,(C14*$S$5+D14*$S$6+E14*$S$7+F14*$S$8+G14*$S$9+H14*$S$10+I14*$S$11+J14*$S$12+K14*$S$13+L14*$S$14+M14*$S$15+N14*$S$16+O14*$S$17+P14*$S$18+Q14*$S$19)/S14) -> 0
A15: ='Kriteria&Bobot'!E16 -> 1 | B15: ='Kriteria&Bobot'!D16 -> 0 | C15: =IF(OR(C3=1,$A$15=1),1,$A$15/C3) -> 1 | D15: =IF(OR(D3=1,$A$15=1),1,$A$15/D3) -> 1 | E15: =IF(OR(E3=1,$A$15=1),1,$A$15/E3) -> 1 | F15: =IF(OR(F3=1,$A$15=1),1,$A$15/F3) -> 1 | G15: =IF(OR(G3=1,$A$15=1),1,$A$15/G3) -> 1 | H15: =IF(OR(H3=1,$A$15=1),1,$A$15/H3) -> 1 | I15: =IF(OR(I3=1,$A$15=1),1,$A$15/I3) -> 1 | J15: =IF(OR(J3=1,$A$15=1),1,$A$15/J3) -> 1 | ... Q15: =IF(OR(Q3=1,$A$15=1),1,$A$15/Q3) -> 1 | R15: =IF(A15=1,0,(C15*D15*E15*F15*G15*H15*I15*J15*K15*L15*M15*N15*O15*P15*Q15)^(1/'Kriteria&Bobot'!$E$3)) -> 0 | S15: =R15/$R$20 -> #DIV/0! | T15: =IF(A15=1,0,(C15*$S$5+D15*$S$6+E15*$S$7+F15*$S$8+G15*$S$9+H15*$S$10+I15*$S$11+J15*$S$12+K15*$S$13+L15*$S$14+M15*$S$15+N15*$S$16+O15*$S$17+P15*$S$18+Q15*$S$19)/S15) -> 0
A16: ='Kriteria&Bobot'!E17 -> 1 | B16: ='Kriteria&Bobot'!D17 -> 0 | C16: =IF(OR(C3=1,$A$16=1),1,$A$16/C3) -> 1 | D16: =IF(OR(D3=1,$A$16=1),1,$A$16/D3) -> 1 | E16: =IF(OR(E3=1,$A$16=1),1,$A$16/E3) -> 1 | F16: =IF(OR(F3=1,$A$16=1),1,$A$16/F3) -> 1 | G16: =IF(OR(G3=1,$A$16=1),1,$A$16/G3) -> 1 | H16: =IF(OR(H3=1,$A$16=1),1,$A$16/H3) -> 1 | I16: =IF(OR(I3=1,$A$16=1),1,$A$16/I3) -> 1 | J16: =IF(OR(J3=1,$A$16=1),1,$A$16/J3) -> 1 | ... Q16: =IF(OR(Q3=1,$A$16=1),1,$A$16/Q3) -> 1 | R16: =IF(A16=1,0,(C16*D16*E16*F16*G16*H16*I16*J16*K16*L16*M16*N16*O16*P16*Q16)^(1/'Kriteria&Bobot'!$E$3)) -> 0 | S16: =R16/$R$20 -> #DIV/0! | T16: =IF(A16=1,0,(C16*$S$5+D16*$S$6+E16*$S$7+F16*$S$8+G16*$S$9+H16*$S$10+I16*$S$11+J16*$S$12+K16*$S$13+L16*$S$14+M16*$S$15+N16*$S$16+O16*$S$17+P16*$S$18+Q16*$S$19)/S16) -> 0
A17: ='Kriteria&Bobot'!E18 -> 1 | B17: ='Kriteria&Bobot'!D18 -> 0 | C17: =IF(OR(C3=1,$A$17=1),1,$A$17/C3) -> 1 | D17: =IF(OR(D3=1,$A$17=1),1,$A$17/D3) -> 1 | E17: =IF(OR(E3=1,$A$17=1),1,$A$17/E3) -> 1 | F17: =IF(OR(F3=1,$A$17=1),1,$A$17/F3) -> 1 | G17: =IF(OR(G3=1,$A$17=1),1,$A$17/G3) -> 1 | H17: =IF(OR(H3=1,$A$17=1),1,$A$17/H3) -> 1 | I17: =IF(OR(I3=1,$A$17=1),1,$A$17/I3) -> 1 | J17: =IF(OR(J3=1,$A$17=1),1,$A$17/J3) -> 1 | ... Q17: =IF(OR(Q3=1,$A$17=1),1,$A$17/Q3) -> 1 | R17: =IF(A17=1,0,(C17*D17*E17*F17*G17*H17*I17*J17*K17*L17*M17*N17*O17*P17*Q17)^(1/'Kriteria&Bobot'!$E$3)) -> 0 | S17: =R17/$R$20 -> #DIV/0! | T17: =IF(A17=1,0,(C17*$S$5+D17*$S$6+E17*$S$7+F17*$S$8+G17*$S$9+H17*$S$10+I17*$S$11+J17*$S$12+K17*$S$13+L17*$S$14+M17*$S$15+N17*$S$16+O17*$S$17+P17*$S$18+Q17*$S$19)/S17) -> 0
A18: ='Kriteria&Bobot'!E19 -> 1 | B18: ='Kriteria&Bobot'!D19 -> 0 | C18: =IF(OR(C3=1,$A$18=1),1,$A$18/C3) -> 1 | D18: =IF(OR(D3=1,$A$18=1),1,$A$18/D3) -> 1 | E18: =IF(OR(E3=1,$A$18=1),1,$A$18/E3) -> 1 | F18: =IF(OR(F3=1,$A$18=1),1,$A$18/F3) -> 1 | G18: =IF(OR(G3=1,$A$18=1),1,$A$18/G3) -> 1 | H18: =IF(OR(H3=1,$A$18=1),1,$A$18/H3) -> 1 | I18: =IF(OR(I3=1,$A$18=1),1,$A$18/I3) -> 1 | J18: =IF(OR(J3=1,$A$18=1),1,$A$18/J3) -> 1 | ... Q18: =IF(OR(Q3=1,$A$18=1),1,$A$18/Q3) -> 1 | R18: =IF(A18=1,0,(C18*D18*E18*F18*G18*H18*I18*J18*K18*L18*M18*N18*O18*P18*Q18)^(1/'Kriteria&Bobot'!$E$3)) -> 0 | S18: =R18/$R$20 -> #DIV/0! | T18: =IF(A18=1,0,(C18*$S$5+D18*$S$6+E18*$S$7+F18*$S$8+G18*$S$9+H18*$S$10+I18*$S$11+J18*$S$12+K18*$S$13+L18*$S$14+M18*$S$15+N18*$S$16+O18*$S$17+P18*$S$18+Q18*$S$19)/S18) -> 0
A19: ='Kriteria&Bobot'!E20 -> 1 | B19: ='Kriteria&Bobot'!D20 -> 0 | C19: =IF(OR(C3=1,$A$19=1),1,$A$19/C3) -> 1 | D19: =IF(OR(D3=1,$A$19=1),1,$A$19/D3) -> 1 | E19: =IF(OR(E3=1,$A$19=1),1,$A$19/E3) -> 1 | F19: =IF(OR(F3=1,$A$19=1),1,$A$19/F3) -> 1 | G19: =IF(OR(G3=1,$A$19=1),1,$A$19/G3) -> 1 | H19: =IF(OR(H3=1,$A$19=1),1,$A$19/H3) -> 1 | I19: =IF(OR(I3=1,$A$19=1),1,$A$19/I3) -> 1 | J19: =IF(OR(J3=1,$A$19=1),1,$A$19/J3) -> 1 | ... Q19: =IF(OR(Q3=1,$A$19=1),1,$A$19/Q3) -> 1 | R19: =IF(A19=1,0,(C19*D19*E19*F19*G19*H19*I19*J19*K19*L19*M19*N19*O19*P19*Q19)^(1/'Kriteria&Bobot'!$E$3)) -> 0 | S19: =R19/$R$20 -> #DIV/0! | T19: =IF(A19=1,0,(C19*$S$5+D19*$S$6+E19*$S$7+F19*$S$8+G19*$S$9+H19*$S$10+I19*$S$11+J19*$S$12+K19*$S$13+L19*$S$14+M19*$S$15+N19*$S$16+O19*$S$17+P19*$S$18+Q19*$S$19)/S19) -> 0
R20: =SUM(R5:R19) -> 0 | S20: =SUM(S5:S19) -> #DIV/0! | T20: =MAX(T5:T19) -> 0
S22: λ avg | T22: =T20 -> 0
B23: TABEL RANDOM INDEX SAATY | E23: ='Kriteria&Bobot'!E3 -> 0 | F23: Kriteria | S23: CI | T23: =(T22-E23)/(E23-1) -> 0
S24: RI | T24: =IF(E23=E25,E26,IF(E23=F25,F26,IF(E23=G25,G26,IF(E23=H25,H26,IF(E23=I25,I26,IF(E23=J25,J26,IF(E23=K25,K26,IF(E23=L25,L26,IF(E23=M25,M26,IF(E23=N25,N26,IF(E23=O25,O26,IF(E23=P25,P26,IF(E23=Q25,Q26))))))))))))) -> FALSE
B25: N | C25: 1 | D25: 2 | E25: 3 | F25: 4 | G25: 5 | H25: 6 | I25: 7 | J25: 8 | K25: 9 | L25: 10 | M25: 11 | N25: 12 | O25: 13 | P25: 14 | Q25: 15 | S25: CR | T25: =T23/T24 -> #DIV/0!
B26: RI | C26: 0 | D26: 0 | E26: 0.58 | F26: 0.9 | G26: 1.12 | H26: 1.24 | I26: 1.32 | J26: 1.41 | K26: 1.45 | L26: 1.49 | M26: 1.51 | N26: 1.54 | O26: 1.56 | P26: 1.57 | Q26: 1.58
S27: Konsisten | T27: IF CR < 1

Sheet Eig Vec Data Kriteria
H1: PERHITUNGAN EIGENVECTOR DAN KONSISTENSI DATA SETIAP KRITERIA
A2: KRITERIA | B2: ='Data Kriteria'!C5 -> 0
C3: {=TRANSPOSE(A5:A19)} -> 1 | D3: 1 | E3: 1 | F3: 1 | G3: 1 | H3: 1 | I3: 1 | J3: 1 | K3: 1 | L3: 1 | M3: 1 | N3: 1 | O3: 1 | P3: 1 | Q3: 1
B4: 1 | C4: {=TRANSPOSE(B5:B19)} -> 0 | D4: 0 | E4: 0 | F4: 0 | G4: 0 | H4: 0 | I4: 0 | J4: 0 | K4: 0 | L4: 0 | M4: 0 | N4: 0 | O4: 0 | P4: 0 | Q4: 0 | R4: nth root | S4: Eigenvector | T4: Eigen value
A5: ='Data Kriteria'!C6 -> 1 | B5: ='Data Kriteria'!B6 -> 0 | C5: =IF(OR(C3=1,$A$5=1),1,$A$5/C3) -> 1 | D5: =IF(OR(D3=1,$A$5=1),1,$A$5/D3) -> 1 | E5: =IF(OR(E3=1,$A$5=1),1,$A$5/E3) -> 1 | F5: =IF(OR(F3=1,$A$5=1),1,$A$5/F3) -> 1 | G5: =IF(OR(G3=1,$A$5=1),1,$A$5/G3) -> 1 | H5: =IF(OR(H3=1,$A$5=1),1,$A$5/H3) -> 1 | I5: =IF(OR(I3=1,$A$5=1),1,$A$5/I3) -> 1 | J5: =IF(OR(J3=1,$A$5=1),1,$A$5/J3) -> 1 | ... Q5: =IF(OR(Q3=1,$A$5=1),1,$A$5/Q3) -> 1 | R5: =IF(A5=1,0,(C5*D5*E5*F5*G5*H5*I5*J5*K5*L5*M5*N5*O5*P5*Q5)^(1/$E$23)) -> 0 | S5: =IF(C4=0,0,R5/$R$20) -> 0 | T5: =IF(A5=1,0,(C5*$S$5+D5*$S$6+E5*$S$7+F5*$S$8+G5*$S$9+H5*$S$10+I5*$S$11+J5*$S$12+K5*$S$13+L5*$S$14+M5*$S$15+N5*$S$16+O5*$S$17+P5*$S$18+Q5*$S$19)/S5) -> 0
A6: ='Data Kriteria'!C7 -> 1 | B6: ='Data Kriteria'!B7 -> 0 | C6: =IF(OR(C3=1,$A$6=1),1,$A$6/C3) -> 1 | D6: =IF(OR(D3=1,$A$6=1),1,$A$6/D3) -> 1 | E6: =IF(OR(E3=1,$A$6=1),1,$A$6/E3) -> 1 | F6: =IF(OR(F3=1,$A$6=1),1,$A$6/F3) -> 1 | G6: =IF(OR(G3=1,$A$6=1),1,$A$6/G3) -> 1 | H6: =IF(OR(H3=1,$A$6=1),1,$A$6/H3) -> 1 | I6: =IF(OR(I3=1,$A$6=1),1,$A$6/I3) -> 1 | J6: =IF(OR(J3=1,$A$6=1),1,$A$6/J3) -> 1 | ... Q6: =IF(OR(Q3=1,$A$6=1),1,$A$6/Q3) -> 1 | R6: =IF(A6=1,0,(C6*D6*E6*F6*G6*H6*I6*J6*K6*L6*M6*N6*O6*P6*Q6)^(1/$E$23)) -> 0 | S6: =IF(D4=0,0,R6/$R$20) -> 0 | T6: =IF(A6=1,0,(C6*$S$5+D6*$S$6+E6*$S$7+F6*$S$8+G6*$S$9+H6*$S$10+I6*$S$11+J6*$S$12+K6*$S$13+L6*$S$14+M6*$S$15+N6*$S$16+O6*$S$17+P6*$S$18+Q6*$S$19)/S6) -> 0
A7: ='Data Kriteria'!C8 -> 1 | B7: ='Data Kriteria'!B8 -> 0 | C7: =IF(OR(C3=1,$A$7=1),1,$A$7/C3) -> 1 | D7: =IF(OR(D3=1,$A$7=1),1,$A$7/D3) -> 1 | E7: =IF(OR(E3=1,$A$7=1),1,$A$7/E3) -> 1 | F7: =IF(OR(F3=1,$A$7=1),1,$A$7/F3) -> 1 | G7: =IF(OR(G3=1,$A$7=1),1,$A$7/G3) -> 1 | H7: =IF(OR(H3=1,$A$7=1),1,$A$7/H3) -> 1 | I7: =IF(OR(I3=1,$A$7=1),1,$A$7/I3) -> 1 | J7: =IF(OR(J3=1,$A$7=1),1,$A$7/J3) -> 1 | ... Q7: =IF(OR(Q3=1,$A$7=1),1,$A$7/Q3) -> 1 | R7: =IF(A7=1,0,(C7*D7*E7*F7*G7*H7*I7*J7*K7*L7*M7*N7*O7*P7*Q7)^(1/$E$23)) -> 0 | S7: =IF(E4=0,0,R7/$R$20) -> 0 | T7: =IF(A7=1,0,(C7*$S$5+D7*$S$6+E7*$S$7+F7*$S$8+G7*$S$9+H7*$S$10+I7*$S$11+J7*$S$12+K7*$S$13+L7*$S$14+M7*$S$15+N7*$S$16+O7*$S$17+P7*$S$18+Q7*$S$19)/S7) -> 0
A8: ='Data Kriteria'!C9 -> 1 | B8: ='Data Kriteria'!B9 -> 0 | C8: =IF(OR(C3=1,$A$8=1),1,$A$8/C3) -> 1 | D8: =IF(OR(D3=1,$A$8=1),1,$A$8/D3) -> 1 | E8: =IF(OR(E3=1,$A$8=1),1,$A$8/E3) -> 1 | F8: =IF(OR(F3=1,$A$8=1),1,$A$8/F3) -> 1 | G8: =IF(OR(G3=1,$A$8=1),1,$A$8/G3) -> 1 | H8: =IF(OR(H3=1,$A$8=1),1,$A$8/H3) -> 1 | I8: =IF(OR(I3=1,$A$8=1),1,$A$8/I3) -> 1 | J8: =IF(OR(J3=1,$A$8=1),1,$A$8/J3) -> 1 | ... Q8: =IF(OR(Q3=1,$A$8=1),1,$A$8/Q3) -> 1 | R8: =IF(A8=1,0,(C8*D8*E8*F8*G8*H8*I8*J8*K8*L8*M8*N8*O8*P8*Q8)^(1/$E$23)) -> 0 | S8: =IF(F4=0,0,R8/$R$20) -> 0 | T8: =IF(A8=1,0,(C8*$S$5+D8*$S$6+E8*$S$7+F8*$S$8+G8*$S$9+H8*$S$10+I8*$S$11+J8*$S$12+K8*$S$13+L8*$S$14+M8*$S$15+N8*$S$16+O8*$S$17+P8*$S$18+Q8*$S$19)/S8) -> 0
A9: ='Data Kriteria'!C10 -> 1 | B9: ='Data Kriteria'!B10 -> 0 | C9: =IF(OR(C3=1,$A$9=1),1,$A$9/C3) -> 1 | D9: =IF(OR(D3=1,$A$9=1),1,$A$9/D3) -> 1 | E9: =IF(OR(E3=1,$A$9=1),1,$A$9/E3) -> 1 | F9: =IF(OR(F3=1,$A$9=1),1,$A$9/F3) -> 1 | G9: =IF(OR(G3=1,$A$9=1),1,$A$9/G3) -> 1 | H9: =IF(OR(H3=1,$A$9=1),1,$A$9/H3) -> 1 | I9: =IF(OR(I3=1,$A$9=1),1,$A$9/I3) -> 1 | J9: =IF(OR(J3=1,$A$9=1),1,$A$9/J3) -> 1 | ... Q9: =IF(OR(Q3=1,$A$9=1),1,$A$9/Q3) -> 1 | R9: =IF(A9=1,0,(C9*D9*E9*F9*G9*H9*I9*J9*K9*L9*M9*N9*O9*P9*Q9)^(1/$E$23)) -> 0 | S9: =IF(G4=0,0,R9/$R$20) -> 0 | T9: =IF(A9=1,0,(C9*$S$5+D9*$S$6+E9*$S$7+F9*$S$8+G9*$S$9+H9*$S$10+I9*$S$11+J9*$S$12+K9*$S$13+L9*$S$14+M9*$S$15+N9*$S$16+O9*$S$17+P9*$S$18+Q9*$S$19)/S9) -> 0
A10: ='Data Kriteria'!C11 -> 1 | B10: ='Data Kriteria'!B11 -> 0 | C10: =IF(OR(C3=1,$A$10=1),1,$A$10/C3) -> 1 | D10: =IF(OR(D3=1,$A$10=1),1,$A$10/D3) -> 1 | E10: =IF(OR(E3=1,$A$10=1),1,$A$10/E3) -> 1 | F10: =IF(OR(F3=1,$A$10=1),1,$A$10/F3) -> 1 | G10: =IF(OR(G3=1,$A$10=1),1,$A$10/G3) -> 1 | H10: =IF(OR(H3=1,$A$10=1),1,$A$10/H3) -> 1 | I10: =IF(OR(I3=1,$A$10=1),1,$A$10/I3) -> 1 | J10: =IF(OR(J3=1,$A$10=1),1,$A$10/J3) -> 1 | ... Q10: =IF(OR(Q3=1,$A$10=1),1,$A$10/Q3) -> 1 | R10: =IF(A10=1,0,(C10*D10*E10*F10*G10*H10*I10*J10*K10*L10*M10*N10*O10*P10*Q10)^(1/$E$23)) -> 0 | S10: =IF(H4=0,0,R10/$R$20) -> 0 | T10: =IF(A10=1,0,(C10*$S$5+D10*$S$6+E10*$S$7+F10*$S$8+G10*$S$9+H10*$S$10+I10*$S$11+J10*$S$12+K10*$S$13+L10*$S$14+M10*$S$15+N10*$S$16+O10*$S$17+P10*$S$18+Q10*$S$19)/S10) -> 0
A11: ='Data Kriteria'!C12 -> 1 | B11: ='Data Kriteria'!B12 -> 0 | C11: =IF(OR(C3=1,$A$11=1),1,$A$11/C3) -> 1 | D11: =IF(OR(D3=1,$A$11=1),1,$A$11/D3) -> 1 | E11: =IF(OR(E3=1,$A$11=1),1,$A$11/E3) -> 1 | F11: =IF(OR(F3=1,$A$11=1),1,$A$11/F3) -> 1 | G11: =IF(OR(G3=1,$A$11=1),1,$A$11/G3) -> 1 | H11: =IF(OR(H3=1,$A$11=1),1,$A$11/H3) -> 1 | I11: =IF(OR(I3=1,$A$11=1),1,$A$11/I3) -> 1 | J11: =IF(OR(J3=1,$A$11=1),1,$A$11/J3) -> 1 | ... Q11: =IF(OR(Q3=1,$A$11=1),1,$A$11/Q3) -> 1 | R11: =IF(A11=1,0,(C11*D11*E11*F11*G11*H11*I11*J11*K11*L11*M11*N11*O11*P11*Q11)^(1/$E$23)) -> 0 | S11: =IF(I4=0,0,R11/$R$20) -> 0 | T11: =IF(A11=1,0,(C11*$S$5+D11*$S$6+E11*$S$7+F11*$S$8+G11*$S$9+H11*$S$10+I11*$S$11+J11*$S$12+K11*$S$13+L11*$S$14+M11*$S$15+N11*$S$16+O11*$S$17+P11*$S$18+Q11*$S$19)/S11) -> 0
A12: ='Data Kriteria'!C13 -> 1 | B12: ='Data Kriteria'!B13 -> 0 | C12: =IF(OR(C3=1,$A$12=1),1,$A$12/C3) -> 1 | D12: =IF(OR(D3=1,$A$12=1),1,$A$12/D3) -> 1 | E12: =IF(OR(E3=1,$A$12=1),1,$A$12/E3) -> 1 | F12: =IF(OR(F3=1,$A$12=1),1,$A$12/F3) -> 1 | G12: =IF(OR(G3=1,$A$12=1),1,$A$12/G3) -> 1 | H12: =IF(OR(H3=1,$A$12=1),1,$A$12/H3) -> 1 | I12: =IF(OR(I3=1,$A$12=1),1,$A$12/I3) -> 1 | J12: =IF(OR(J3=1,$A$12=1),1,$A$12/J3) -> 1 | ... Q12: =IF(OR(Q3=1,$A$12=1),1,$A$12/Q3) -> 1 | R12: =IF(A12=1,0,(C12*D12*E12*F12*G12*H12*I12*J12*K12*L12*M12*N12*O12*P12*Q12)^(1/$E$23)) -> 0 | S12: =IF(J4=0,0,R12/$R$20) -> 0 | T12: =IF(A12=1,0,(C12*$S$5+D12*$S$6+E12*$S$7+F12*$S$8+G12*$S$9+H12*$S$10+I12*$S$11+J12*$S$12+K12*$S$13+L12*$S$14+M12*$S$15+N12*$S$16+O12*$S$17+P12*$S$18+Q12*$S$19)/S12) -> 0
A13: ='Data Kriteria'!C14 -> 1 | B13: ='Data Kriteria'!B14 -> 0 | C13: =IF(OR(C3=1,$A$13=1),1,$A$13/C3) -> 1 | D13: =IF(OR(D3=1,$A$13=1),1,$A$13/D3) -> 1 | E13: =IF(OR(E3=1,$A$13=1),1,$A$13/E3) -> 1 | F13: =IF(OR(F3=1,$A$13=1),1,$A$13/F3) -> 1 | G13: =IF(OR(G3=1,$A$13=1),1,$A$13/G3) -> 1 | H13: =IF(OR(H3=1,$A$13=1),1,$A$13/H3) -> 1 | I13: =IF(OR(I3=1,$A$13=1),1,$A$13/I3) -> 1 | J13: =IF(OR(J3=1,$A$13=1),1,$A$13/J3) -> 1 | ... Q13: =IF(OR(Q3=1,$A$13=1),1,$A$13/Q3) -> 1 | R13: =IF(A13=1,0,(C13*D13*E13*F13*G13*H13*I13*J13*K13*L13*M13*N13*O13*P13*Q13)^(1/$E$23)) -> 0 | S13: =IF(K4=0,0,R13/$R$20) -> 0 | T13: =IF(A13=1,0,(C13*$S$5+D13*$S$6+E13*$S$7+F13*$S$8+G13*$S$9+H13*$S$10+I13*$S$11+J13*$S$12+K13*$S$13+L13*$S$14+M13*$S$15+N13*$S$16+O13*$S$17+P13*$S$18+Q13*$S$19)/S13) -> 0
A14: ='Data Kriteria'!C15 -> 1 | B14: ='Data Kriteria'!B15 -> 0 | C14: =IF(OR(C3=1,$A$14=1),1,$A$14/C3) -> 1 | D14: =IF(OR(D3=1,$A$14=1),1,$A$14/D3) -> 1 | E14: =IF(OR(E3=1,$A$14=1),1,$A$14/E3) -> 1 | F14: =IF(OR(F3=1,$A$14=1),1,$A$14/F3) -> 1 | G14: =IF(OR(G3=1,$A$14=1),1,$A$14/G3) -> 1 | H14: =IF(OR(H3=1,$A$14=1),1,$A$14/H3) -> 1 | I14: =IF(OR(I3=1,$A$14=1),1,$A$14/I3) -> 1 | J14: =IF(OR(J3=1,$A$14=1),1,$A$14/J3) -> 1 | ... Q14: =IF(OR(Q3=1,$A$14=1),1,$A$14/Q3) -> 1 | R14: =IF(A14=1,0,(C14*D14*E14*F14*G14*H14*I14*J14*K14*L14*M14*N14*O14*P14*Q14)^(1/$E$23)) -> 0 | S14: =IF(L4=0,0,R14/$R$20) -> 0 | T14: =IF(A14=1,0,(C14*$S$5+D14*$S$6+E14*$S$7+F14*$S$8+G14*$S$9+H14*$S$10+I14*$S$11+J14*$S$12+K14*$S$13+L14*$S$14+M14*$S$15+N14*$S$16+O14*$S$17+P14*$S$18+Q14*$S$19)/S14) -> 0
A15: ='Data Kriteria'!C16 -> 1 | B15: ='Data Kriteria'!B16 -> 0 | C15: =IF(OR(C3=1,$A$15=1),1,$A$15/C3) -> 1 | D15: =IF(OR(D3=1,$A$15=1),1,$A$15/D3) -> 1 | E15: =IF(OR(E3=1,$A$15=1),1,$A$15/E3) -> 1 | F15: =IF(OR(F3=1,$A$15=1),1,$A$15/F3) -> 1 | G15: =IF(OR(G3=1,$A$15=1),1,$A$15/G3) -> 1 | H15: =IF(OR(H3=1,$A$15=1),1,$A$15/H3) -> 1 | I15: =IF(OR(I3=1,$A$15=1),1,$A$15/I3) -> 1 | J15: =IF(OR(J3=1,$A$15=1),1,$A$15/J3) -> 1 | ... Q15: =IF(OR(Q3=1,$A$15=1),1,$A$15/Q3) -> 1 | R15: =IF(A15=1,0,(C15*D15*E15*F15*G15*H15*I15*J15*K15*L15*M15*N15*O15*P15*Q15)^(1/$E$23)) -> 0 | S15: =IF(M4=0,0,R15/$R$20) -> 0 | T15: =IF(A15=1,0,(C15*$S$5+D15*$S$6+E15*$S$7+F15*$S$8+G15*$S$9+H15*$S$10+I15*$S$11+J15*$S$12+K15*$S$13+L15*$S$14+M15*$S$15+N15*$S$16+O15*$S$17+P15*$S$18+Q15*$S$19)/S15) -> 0
A16: ='Data Kriteria'!C17 -> 1 | B16: ='Data Kriteria'!B17 -> 0 | C16: =IF(OR(C3=1,$A$16=1),1,$A$16/C3) -> 1 | D16: =IF(OR(D3=1,$A$16=1),1,$A$16/D3) -> 1 | E16: =IF(OR(E3=1,$A$16=1),1,$A$16/E3) -> 1 | F16: =IF(OR(F3=1,$A$16=1),1,$A$16/F3) -> 1 | G16: =IF(OR(G3=1,$A$16=1),1,$A$16/G3) -> 1 | H16: =IF(OR(H3=1,$A$16=1),1,$A$16/H3) -> 1 | I16: =IF(OR(I3=1,$A$16=1),1,$A$16/I3) -> 1 | J16: =IF(OR(J3=1,$A$16=1),1,$A$16/J3) -> 1 | ... Q16: =IF(OR(Q3=1,$A$16=1),1,$A$16/Q3) -> 1 | R16: =IF(A16=1,0,(C16*D16*E16*F16*G16*H16*I16*J16*K16*L16*M16*N16*O16*P16*Q16)^(1/$E$23)) -> 0 | S16: =IF(N4=0,0,R16/$R$20) -> 0 | T16: =IF(A16=1,0,(C16*$S$5+D16*$S$6+E16*$S$7+F16*$S$8+G16*$S$9+H16*$S$10+I16*$S$11+J16*$S$12+K16*$S$13+L16*$S$14+M16*$S$15+N16*$S$16+O16*$S$17+P16*$S$18+Q16*$S$19)/S16) -> 0
A17: ='Data Kriteria'!C18 -> 1 | B17: ='Data Kriteria'!B18 -> 0 | C17: =IF(OR(C3=1,$A$17=1),1,$A$17/C3) -> 1 | D17: =IF(OR(D3=1,$A$17=1),1,$A$17/D3) -> 1 | E17: =IF(OR(E3=1,$A$17=1),1,$A$17/E3) -> 1 | F17: =IF(OR(F3=1,$A$17=1),1,$A$17/F3) -> 1 | G17: =IF(OR(G3=1,$A$17=1),1,$A$17/G3) -> 1 | H17: =IF(OR(H3=1,$A$17=1),1,$A$17/H3) -> 1 | I17: =IF(OR(I3=1,$A$17=1),1,$A$17/I3) -> 1 | J17: =IF(OR(J3=1,$A$17=1),1,$A$17/J3) -> 1 | ... Q17: =IF(OR(Q3=1,$A$17=1),1,$A$17/Q3) -> 1 | R17: =IF(A17=1,0,(C17*D17*E17*F17*G17*H17*I17*J17*K17*L17*M17*N17*O17*P17*Q17)^(1/$E$23)) -> 0 | S17: =IF(O4=0,0,R17/$R$20) -> 0 | T17: =IF(A17=1,0,(C17*$S$5+D17*$S$6+E17*$S$7+F17*$S$8+G17*$S$9+H17*$S$10+I17*$S$11+J17*$S$12+K17*$S$13+L17*$S$14+M17*$S$15+N17*$S$16+O17*$S$17+P17*$S$18+Q17*$S$19)/S17) -> 0
A18: ='Data Kriteria'!C19 -> 1 | B18: ='Data Kriteria'!B19 -> 0 | C18: =IF(OR(C3=1,$A$18=1),1,$A$18/C3) -> 1 | D18: =IF(OR(D3=1,$A$18=1),1,$A$18/D3) -> 1 | E18: =IF(OR(E3=1,$A$18=1),1,$A$18/E3) -> 1 | F18: =IF(OR(F3=1,$A$18=1),1,$A$18/F3) -> 1 | G18: =IF(OR(G3=1,$A$18=1),1,$A$18/G3) -> 1 | H18: =IF(OR(H3=1,$A$18=1),1,$A$18/H3) -> 1 | I18: =IF(OR(I3=1,$A$18=1),1,$A$18/I3) -> 1 | J18: =IF(OR(J3=1,$A$18=1),1,$A$18/J3) -> 1 | ... Q18: =IF(OR(Q3=1,$A$18=1),1,$A$18/Q3) -> 1 | R18: =IF(A18=1,0,(C18*D18*E18*F18*G18*H18*I18*J18*K18*L18*M18*N18*O18*P18*Q18)^(1/$E$23)) -> 0 | S18: =IF(P4=0,0,R18/$R$20) -> 0 | T18: =IF(A18=1,0,(C18*$S$5+D18*$S$6+E18*$S$7+F18*$S$8+G18*$S$9+H18*$S$10+I18*$S$11+J18*$S$12+K18*$S$13+L18*$S$14+M18*$S$15+N18*$S$16+O18*$S$17+P18*$S$18+Q18*$S$19)/S18) -> 0
A19: ='Data Kriteria'!C20 -> 1 | B19: ='Data Kriteria'!B20 -> 0 | C19: =IF(OR(C3=1,$A$19=1),1,$A$19/C3) -> 1 | D19: =IF(OR(D3=1,$A$19=1),1,$A$19/D3) -> 1 | E19: =IF(OR(E3=1,$A$19=1),1,$A$19/E3) -> 1 | F19: =IF(OR(F3=1,$A$19=1),1,$A$19/F3) -> 1 | G19: =IF(OR(G3=1,$A$19=1),1,$A$19/G3) -> 1 | H19: =IF(OR(H3=1,$A$19=1),1,$A$19/H3) -> 1 | I19: =IF(OR(I3=1,$A$19=1),1,$A$19/I3) -> 1 | J19: =IF(OR(J3=1,$A$19=1),1,$A$19/J3) -> 1 | ... Q19: =IF(OR(Q3=1,$A$19=1),1,$A$19/Q3) -> 1 | R19: =IF(A19=1,0,(C19*D19*E19*F19*G19*H19*I19*J19*K19*L19*M19*N19*O19*P19*Q19)^(1/$E$23)) -> 0 | S19: =IF(Q4=0,0,R19/$R$20) -> 0 | T19: =IF(A19=1,0,(C19*$S$5+D19*$S$6+E19*$S$7+F19*$S$8+G19*$S$9+H19*$S$10+I19*$S$11+J19*$S$12+K19*$S$13+L19*$S$14+M19*$S$15+N19*$S$16+O19*$S$17+P19*$S$18+Q19*$S$19)/S19) -> 0
R20: =SUM(R5:R19) -> 0 | S20: =SUM(S5:S19) -> 0 | T20: =MAX(T5:T19) -> 0
S22: λ avg/max | T22: =T20 -> 0
B23: TABEL RANDOM INDEX SAATY | E23: =Challanges!D3 -> 0 | S23: CI | T23: =(T22-E23)/(E23-1) -> 0
S24: RI | T24: =IF(E23=E25,E26,IF(E23=F25,F26,IF(E23=G25,G26,IF(E23=H25,H26,IF(E23=I25,I26,IF(E23=J25,J26,IF(E23=K25,K26,IF(E23=L25,L26,IF(E23=M25,M26,IF(E23=N25,N26,IF(E23=O25,O26,IF(E23=P25,P26,IF(E23=Q25,Q26))))))))))))) -> FALSE
B25: N | C25: 1 | D25: 2 | E25: 3 | F25: 4 | G25: 5 | H25: 6 | I25: 7 | J25: 8 | K25: 9 | L25: 10 | M25: 11 | N25: 12 | O25: 13 | P25: 14 | Q25: 15 | S25: CR | T25: =T23/T24 -> #DIV/0!
B26: RI | C26: 0 | D26: 0 | E26: 0.58 | F26: 0.9 | G26: 1.12 | H26: 1.24 | I26: 1.32 | J26: 1.41 | K26: 1.45 | L26: 1.49 | M26: 1.51 | N26: 1.54 | O26: 1.56 | P26: 1.57 | Q26: 1.58
S27: Konsisten | T27: IF CR < 1
A29: KRITERIA | B29: ='Data Kriteria'!D5 -> 0
C30: {=TRANSPOSE(A32:A46)} -> 1 | D30: 1 | E30: 1 | F30: 1 | G30: 1 | H30: 1 | I30: 1 | J30: 1 | K30: 1 | L30: 1 | M30: 1 | N30: 1 | O30: 1 | P30: 1 | Q30: 1
B31: 2 | C31: {=TRANSPOSE(B32:B46)} -> 0 | D31: 0 | E31: 0 | F31: 0 | G31: 0 | H31: 0 | I31: 0 | J31: 0 | K31: 0 | L31: 0 | M31: 0 | N31: 0 | O31: 0 | P31: 0 | Q31: 0 | R31: nth root | S31: Eigenvector | T31: Eigen value
A32: ='Data Kriteria'!D6 -> 1 | B32: ='Data Kriteria'!B6 -> 0 | C32: =IF(OR(C30=1,$A$32=1),1,$A$32/C30) -> 1 | D32: =IF(OR(D30=1,$A$32=1),1,$A$32/D30) -> 1 | E32: =IF(OR(E30=1,$A$32=1),1,$A$32/E30) -> 1 | F32: =IF(OR(F30=1,$A$32=1),1,$A$32/F30) -> 1 | G32: =IF(OR(G30=1,$A$32=1),1,$A$32/G30) -> 1 | H32: =IF(OR(H30=1,$A$32=1),1,$A$32/H30) -> 1 | I32: =IF(OR(I30=1,$A$32=1),1,$A$32/I30) -> 1 | J32: =IF(OR(J30=1,$A$32=1),1,$A$32/J30) -> 1 | ... Q32: =IF(OR(Q30=1,$A$32=1),1,$A$32/Q30) -> 1 | R32: =IF(A32=1,0,(C32*D32*E32*F32*G32*H32*I32*J32*K32*L32*M32*N32*O32*P32*Q32)^(1/$E$50)) -> 0 | S32: =IF(C31=0,0,R32/$R$47) -> 0 | T32: =IF(A32=1,0,(C32*$S$5+D32*$S$6+E32*$S$7+F32*$S$8+G32*$S$9+H32*$S$10+I32*$S$11+J32*$S$12+K32*$S$13+L32*$S$14+M32*$S$15+N32*$S$16+O32*$S$17+P32*$S$18+Q32*$S$19)/S32) -> 0
A33: ='Data Kriteria'!D7 -> 1 | B33: ='Data Kriteria'!B7 -> 0 | C33: =IF(OR(C30=1,$A$33=1),1,$A$33/C30) -> 1 | D33: =IF(OR(D30=1,$A$33=1),1,$A$33/D30) -> 1 | E33: =IF(OR(E30=1,$A$33=1),1,$A$33/E30) -> 1 | F33: =IF(OR(F30=1,$A$33=1),1,$A$33/F30) -> 1 | G33: =IF(OR(G30=1,$A$33=1),1,$A$33/G30) -> 1 | H33: =IF(OR(H30=1,$A$33=1),1,$A$33/H30) -> 1 | I33: =IF(OR(I30=1,$A$33=1),1,$A$33/I30) -> 1 | J33: =IF(OR(J30=1,$A$33=1),1,$A$33/J30) -> 1 | ... Q33: =IF(OR(Q30=1,$A$33=1),1,$A$33/Q30) -> 1 | R33: =IF(A33=1,0,(C33*D33*E33*F33*G33*H33*I33*J33*K33*L33*M33*N33*O33*P33*Q33)^(1/$E$50)) -> 0 | S33: =IF(D31=0,0,R33/$R$47) -> 0 | T33: =IF(A33=1,0,(C33*$S$5+D33*$S$6+E33*$S$7+F33*$S$8+G33*$S$9+H33*$S$10+I33*$S$11+J33*$S$12+K33*$S$13+L33*$S$14+M33*$S$15+N33*$S$16+O33*$S$17+P33*$S$18+Q33*$S$19)/S33) -> 0
A34: ='Data Kriteria'!D8 -> 1 | B34: ='Data Kriteria'!B8 -> 0 | C34: =IF(OR(C30=1,$A$34=1),1,$A$34/C30) -> 1 | D34: =IF(OR(D30=1,$A$34=1),1,$A$34/D30) -> 1 | E34: =IF(OR(E30=1,$A$34=1),1,$A$34/E30) -> 1 | F34: =IF(OR(F30=1,$A$34=1),1,$A$34/F30) -> 1 | G34: =IF(OR(G30=1,$A$34=1),1,$A$34/G30) -> 1 | H34: =IF(OR(H30=1,$A$34=1),1,$A$34/H30) -> 1 | I34: =IF(OR(I30=1,$A$34=1),1,$A$34/I30) -> 1 | J34: =IF(OR(J30=1,$A$34=1),1,$A$34/J30) -> 1 | ... Q34: =IF(OR(Q30=1,$A$34=1),1,$A$34/Q30) -> 1 | R34: =IF(A34=1,0,(C34*D34*E34*F34*G34*H34*I34*J34*K34*L34*M34*N34*O34*P34*Q34)^(1/$E$50)) -> 0 | S34: =IF(E31=0,0,R34/$R$47) -> 0 | T34: =IF(A34=1,0,(C34*$S$5+D34*$S$6+E34*$S$7+F34*$S$8+G34*$S$9+H34*$S$10+I34*$S$11+J34*$S$12+K34*$S$13+L34*$S$14+M34*$S$15+N34*$S$16+O34*$S$17+P34*$S$18+Q34*$S$19)/S34) -> 0
A35: ='Data Kriteria'!D9 -> 1 | B35: ='Data Kriteria'!B9 -> 0 | C35: =IF(OR(C30=1,$A$35=1),1,$A$35/C30) -> 1 | D35: =IF(OR(D30=1,$A$35=1),1,$A$35/D30) -> 1 | E35: =IF(OR(E30=1,$A$35=1),1,$A$35/E30) -> 1 | F35: =IF(OR(F30=1,$A$35=1),1,$A$35/F30) -> 1 | G35: =IF(OR(G30=1,$A$35=1),1,$A$35/G30) -> 1 | H35: =IF(OR(H30=1,$A$35=1),1,$A$35/H30) -> 1 | I35: =IF(OR(I30=1,$A$35=1),1,$A$35/I30) -> 1 | J35: =IF(OR(J30=1,$A$35=1),1,$A$35/J30) -> 1 | ... Q35: =IF(OR(Q30=1,$A$35=1),1,$A$35/Q30) -> 1 | R35: =IF(A35=1,0,(C35*D35*E35*F35*G35*H35*I35*J35*K35*L35*M35*N35*O35*P35*Q35)^(1/$E$50)) -> 0 | S35: =IF(F31=0,0,R35/$R$47) -> 0 | T35: =IF(A35=1,0,(C35*$S$5+D35*$S$6+E35*$S$7+F35*$S$8+G35*$S$9+H35*$S$10+I35*$S$11+J35*$S$12+K35*$S$13+L35*$S$14+M35*$S$15+N35*$S$16+O35*$S$17+P35*$S$18+Q35*$S$19)/S35) -> 0
A36: ='Data Kriteria'!D10 -> 1 | B36: ='Data Kriteria'!B10 -> 0 | C36: =IF(OR(C30=1,$A$36=1),1,$A$36/C30) -> 1 | D36: =IF(OR(D30=1,$A$36=1),1,$A$36/D30) -> 1 | E36: =IF(OR(E30=1,$A$36=1),1,$A$36/E30) -> 1 | F36: =IF(OR(F30=1,$A$36=1),1,$A$36/F30) -> 1 | G36: =IF(OR(G30=1,$A$36=1),1,$A$36/G30) -> 1 | H36: =IF(OR(H30=1,$A$36=1),1,$A$36/H30) -> 1 | I36: =IF(OR(I30=1,$A$36=1),1,$A$36/I30) -> 1 | J36: =IF(OR(J30=1,$A$36=1),1,$A$36/J30) -> 1 | ... Q36: =IF(OR(Q30=1,$A$36=1),1,$A$36/Q30) -> 1 | R36: =IF(A36=1,0,(C36*D36*E36*F36*G36*H36*I36*J36*K36*L36*M36*N36*O36*P36*Q36)^(1/$E$50)) -> 0 | S36: =IF(G31=0,0,R36/$R$47) -> 0 | T36: =IF(A36=1,0,(C36*$S$5+D36*$S$6+E36*$S$7+F36*$S$8+G36*$S$9+H36*$S$10+I36*$S$11+J36*$S$12+K36*$S$13+L36*$S$14+M36*$S$15+N36*$S$16+O36*$S$17+P36*$S$18+Q36*$S$19)/S36) -> 0
A37: ='Data Kriteria'!D11 -> 1 | B37: ='Data Kriteria'!B11 -> 0 | C37: =IF(OR(C30=1,$A$37=1),1,$A$37/C30) -> 1 | D37: =IF(OR(D30=1,$A$37=1),1,$A$37/D30) -> 1 | E37: =IF(OR(E30=1,$A$37=1),1,$A$37/E30) -> 1 | F37: =IF(OR(F30=1,$A$37=1),1,$A$37/F30) -> 1 | G37: =IF(OR(G30=1,$A$37=1),1,$A$37/G30) -> 1 | H37: =IF(OR(H30=1,$A$37=1),1,$A$37/H30) -> 1 | I37: =IF(OR(I30=1,$A$37=1),1,$A$37/I30) -> 1 | J37: =IF(OR(J30=1,$A$37=1),1,$A$37/J30) -> 1 | ... Q37: =IF(OR(Q30=1,$A$37=1),1,$A$37/Q30) -> 1 | R37: =IF(A37=1,0,(C37*D37*E37*F37*G37*H37*I37*J37*K37*L37*M37*N37*O37*P37*Q37)^(1/$E$50)) -> 0 | S37: =IF(H31=0,0,R37/$R$47) -> 0 | T37: =IF(A37=1,0,(C37*$S$5+D37*$S$6+E37*$S$7+F37*$S$8+G37*$S$9+H37*$S$10+I37*$S$11+J37*$S$12+K37*$S$13+L37*$S$14+M37*$S$15+N37*$S$16+O37*$S$17+P37*$S$18+Q37*$S$19)/S37) -> 0
A38: ='Data Kriteria'!D12 -> 1 | B38: ='Data Kriteria'!B12 -> 0 | C38: =IF(OR(C30=1,$A$38=1),1,$A$38/C30) -> 1 | D38: =IF(OR(D30=1,$A$38=1),1,$A$38/D30) -> 1 | E38: =IF(OR(E30=1,$A$38=1),1,$A$38/E30) -> 1 | F38: =IF(OR(F30=1,$A$38=1),1,$A$38/F30) -> 1 | G38: =IF(OR(G30=1,$A$38=1),1,$A$38/G30) -> 1 | H38: =IF(OR(H30=1,$A$38=1),1,$A$38/H30) -> 1 | I38: =IF(OR(I30=1,$A$38=1),1,$A$38/I30) -> 1 | J38: =IF(OR(J30=1,$A$38=1),1,$A$38/J30) -> 1 | ... Q38: =IF(OR(Q30=1,$A$38=1),1,$A$38/Q30) -> 1 | R38: =IF(A38=1,0,(C38*D38*E38*F38*G38*H38*I38*J38*K38*L38*M38*N38*O38*P38*Q38)^(1/$E$50)) -> 0 | S38: =IF(I31=0,0,R38/$R$47) -> 0 | T38: =IF(A38=1,0,(C38*$S$5+D38*$S$6+E38*$S$7+F38*$S$8+G38*$S$9+H38*$S$10+I38*$S$11+J38*$S$12+K38*$S$13+L38*$S$14+M38*$S$15+N38*$S$16+O38*$S$17+P38*$S$18+Q38*$S$19)/S38) -> 0
A39: ='Data Kriteria'!D13 -> 1 | B39: ='Data Kriteria'!B13 -> 0 | C39: =IF(OR(C30=1,$A$39=1),1,$A$39/C30) -> 1 | D39: =IF(OR(D30=1,$A$39=1),1,$A$39/D30) -> 1 | E39: =IF(OR(E30=1,$A$39=1),1,$A$39/E30) -> 1 | F39: =IF(OR(F30=1,$A$39=1),1,$A$39/F30) -> 1 | G39: =IF(OR(G30=1,$A$39=1),1,$A$39/G30) -> 1 | H39: =IF(OR(H30=1,$A$39=1),1,$A$39/H30) -> 1 | I39: =IF(OR(I30=1,$A$39=1),1,$A$39/I30) -> 1 | J39: =IF(OR(J30=1,$A$39=1),1,$A$39/J30) -> 1 | ... Q39: =IF(OR(Q30=1,$A$39=1),1,$A$39/Q30) -> 1 | R39: =IF(A39=1,0,(C39*D39*E39*F39*G39*H39*I39*J39*K39*L39*M39*N39*O39*P39*Q39)^(1/$E$50)) -> 0 | S39: =IF(J31=0,0,R39/$R$47) -> 0 | T39: =IF(A39=1,0,(C39*$S$5+D39*$S$6+E39*$S$7+F39*$S$8+G39*$S$9+H39*$S$10+I39*$S$11+J39*$S$12+K39*$S$13+L39*$S$14+M39*$S$15+N39*$S$16+O39*$S$17+P39*$S$18+Q39*$S$19)/S39) -> 0
A40: ='Data Kriteria'!D14 -> 1 | B40: ='Data Kriteria'!B14 -> 0 | C40: =IF(OR(C30=1,$A$40=1),1,$A$40/C30) -> 1 | D40: =IF(OR(D30=1,$A$40=1),1,$A$40/D30) -> 1 | E40: =IF(OR(E30=1,$A$40=1),1,$A$40/E30) -> 1 | F40: =IF(OR(F30=1,$A$40=1),1,$A$40/F30) -> 1 | G40: =IF(OR(G30=1,$A$40=1),1,$A$40/G30) -> 1 | H40: =IF(OR(H30=1,$A$40=1),1,$A$40/H30) -> 1 | I40: =IF(OR(I30=1,$A$40=1),1,$A$40/I30) -> 1 | J40: =IF(OR(J30=1,$A$40=1),1,$A$40/J30) -> 1 | ... Q40: =IF(OR(Q30=1,$A$40=1),1,$A$40/Q30) -> 1 | R40: =IF(A40=1,0,(C40*D40*E40*F40*G40*H40*I40*J40*K40*L40*M40*N40*O40*P40*Q40)^(1/$E$50)) -> 0 | S40: =IF(K31=0,0,R40/$R$47) -> 0 | T40: =IF(A40=1,0,(C40*$S$5+D40*$S$6+E40*$S$7+F40*$S$8+G40*$S$9+H40*$S$10+I40*$S$11+J40*$S$12+K40*$S$13+L40*$S$14+M40*$S$15+N40*$S$16+O40*$S$17+P40*$S$18+Q40*$S$19)/S40) -> 0
A41: ='Data Kriteria'!D15 -> 1 | B41: ='Data Kriteria'!B15 -> 0 | C41: =IF(OR(C30=1,$A$41=1),1,$A$41/C30) -> 1 | D41: =IF(OR(D30=1,$A$41=1),1,$A$41/D30) -> 1 | E41: =IF(OR(E30=1,$A$41=1),1,$A$41/E30) -> 1 | F41: =IF(OR(F30=1,$A$41=1),1,$A$41/F30) -> 1 | G41: =IF(OR(G30=1,$A$41=1),1,$A$41/G30) -> 1 | H41: =IF(OR(H30=1,$A$41=1),1,$A$41/H30) -> 1 | I41: =IF(OR(I30=1,$A$41=1),1,$A$41/I30) -> 1 | J41: =IF(OR(J30=1,$A$41=1),1,$A$41/J30) -> 1 | ... Q41: =IF(OR(Q30=1,$A$41=1),1,$A$41/Q30) -> 1 | R41: =IF(A41=1,0,(C41*D41*E41*F41*G41*H41*I41*J41*K41*L41*M41*N41*O41*P41*Q41)^(1/$E$50)) -> 0 | S41: =IF(L31=0,0,R41/$R$47) -> 0 | T41: =IF(A41=1,0,(C41*$S$5+D41*$S$6+E41*$S$7+F41*$S$8+G41*$S$9+H41*$S$10+I41*$S$11+J41*$S$12+K41*$S$13+L41*$S$14+M41*$S$15+N41*$S$16+O41*$S$17+P41*$S$18+Q41*$S$19)/S41) -> 0
A42: ='Data Kriteria'!D16 -> 1 | B42: ='Data Kriteria'!B16 -> 0 | C42: =IF(OR(C30=1,$A$42=1),1,$A$42/C30) -> 1 | D42: =IF(OR(D30=1,$A$42=1),1,$A$42/D30) -> 1 | E42: =IF(OR(E30=1,$A$42=1),1,$A$42/E30) -> 1 | F42: =IF(OR(F30=1,$A$42=1),1,$A$42/F30) -> 1 | G42: =IF(OR(G30=1,$A$42=1),1,$A$42/G30) -> 1 | H42: =IF(OR(H30=1,$A$42=1),1,$A$42/H30) -> 1 | I42: =IF(OR(I30=1,$A$42=1),1,$A$42/I30) -> 1 | J42: =IF(OR(J30=1,$A$42=1),1,$A$42/J30) -> 1 | ... Q42: =IF(OR(Q30=1,$A$42=1),1,$A$42/Q30) -> 1 | R42: =IF(A42=1,0,(C42*D42*E42*F42*G42*H42*I42*J42*K42*L42*M42*N42*O42*P42*Q42)^(1/$E$50)) -> 0 | S42: =IF(M31=0,0,R42/$R$47) -> 0 | T42: =IF(A42=1,0,(C42*$S$5+D42*$S$6+E42*$S$7+F42*$S$8+G42*$S$9+H42*$S$10+I42*$S$11+J42*$S$12+K42*$S$13+L42*$S$14+M42*$S$15+N42*$S$16+O42*$S$17+P42*$S$18+Q42*$S$19)/S42) -> 0
...

Sheet FINAL MATRIK
A1: MATRIK PERHITUNGAN PERINGKAT CHALLENGES
A3: Kode Challs | B3: Eigen Vector Challenges Setiap Kriteria | Q3: EV Bobot | R3: HASIL
B4: ='Data Kriteria'!C5 -> 0 | C4: ='Data Kriteria'!D5 -> 0 | D4: ='Data Kriteria'!E5 -> 0 | E4: ='Data Kriteria'!F5 -> 0 | F4: ='Data Kriteria'!G5 -> 0 | G4: ='Data Kriteria'!H5 -> 0 | H4: ='Data Kriteria'!I5 -> 0 | I4: ='Data Kriteria'!J5 -> 0 | ... P4: ='Data Kriteria'!Q5 -> 0 | Q4: KRITERIA | R4: FINAL
A5: ='Data Kriteria'!B6 -> 0 | B5: ='Eig Vec Data Kriteria'!S5 -> 0 | C5: ='Eig Vec Data Kriteria'!S32 -> 0 | D5: ='Eig Vec Data Kriteria'!S59 -> 0 | E5: ='Eig Vec Data Kriteria'!S86 -> 0 | F5: ='Eig Vec Data Kriteria'!S113 -> 0 | G5: ='Eig Vec Data Kriteria'!S140 -> 0 | H5: ='Eig Vec Data Kriteria'!S167 -> 0 | I5: ='Eig Vec Data Kriteria'!S194 -> 0 | J5: ='Eig Vec Data Kriteria'!S221 -> 0 | K5: ='Eig Vec Data Kriteria'!S248 -> 0 | L5: ='Eig Vec Data Kriteria'!S275 -> 0 | M5: ='Eig Vec Data Kriteria'!S302 -> 0 | N5: ='Eig Vec Data Kriteria'!S329 -> 0 | O5: ='Eig Vec Data Kriteria'!S356 -> 0 | P5: ='Eig Vec Data Kriteria'!S383 -> 0 | Q5: ='Eig Vec Bobot Kriteria'!S5 -> #DIV/0! | R5: =B5*$Q$5+C5*$Q$6+D5*$Q$7+E5*$Q$8+F5*$Q$9+G5*$Q$10+H5*$Q$11+I5*$Q$12+J5*$Q$13+K5*$Q$14+L5*$Q$15+M5*$Q$16+N5*$Q$17+O5*$Q$18+P5*$Q$19 -> #DIV/0!
A6: ='Data Kriteria'!B7 -> 0 | B6: ='Eig Vec Data Kriteria'!S6 -> 0 | C6: ='Eig Vec Data Kriteria'!S33 -> 0 | D6: ='Eig Vec Data Kriteria'!S60 -> 0 | E6: ='Eig Vec Data Kriteria'!S87 -> 0 | F6: ='Eig Vec Data Kriteria'!S114 -> 0 | G6: ='Eig Vec Data Kriteria'!S141 -> 0 | H6: ='Eig Vec Data Kriteria'!S168 -> 0 | I6: ='Eig Vec Data Kriteria'!S195 -> 0 | J6: ='Eig Vec Data Kriteria'!S222 -> 0 | K6: ='Eig Vec Data Kriteria'!S249 -> 0 | L6: ='Eig Vec Data Kriteria'!S276 -> 0 | M6: ='Eig Vec Data Kriteria'!S303 -> 0 | N6: ='Eig Vec Data Kriteria'!S330 -> 0 | O6: ='Eig Vec Data Kriteria'!S357 -> 0 | P6: ='Eig Vec Data Kriteria'!S384 -> 0 | Q6: ='Eig Vec Bobot Kriteria'!S6 -> #DIV/0! | R6: =B6*$Q$5+C6*$Q$6+D6*$Q$7+E6*$Q$8+F6*$Q$9+G6*$Q$10+H6*$Q$11+I6*$Q$12+J6*$Q$13+K6*$Q$14+L6*$Q$15+M6*$Q$16+N6*$Q$17+O6*$Q$18+P6*$Q$19 -> #DIV/0!
A7: ='Data Kriteria'!B8 -> 0 | B7: ='Eig Vec Data Kriteria'!S7 -> 0 | C7: ='Eig Vec Data Kriteria'!S34 -> 0 | D7: ='Eig Vec Data Kriteria'!S61 -> 0 | E7: ='Eig Vec Data Kriteria'!S88 -> 0 | F7: ='Eig Vec Data Kriteria'!S115 -> 0 | G7: ='Eig Vec Data Kriteria'!S142 -> 0 | H7: ='Eig Vec Data Kriteria'!S169 -> 0 | I7: ='Eig Vec Data Kriteria'!S196 -> 0 | J7: ='Eig Vec Data Kriteria'!S223 -> 0 | K7: ='Eig Vec Data Kriteria'!S250 -> 0 | L7: ='Eig Vec Data Kriteria'!S277 -> 0 | M7: ='Eig Vec Data Kriteria'!S304 -> 0 | N7: ='Eig Vec Data Kriteria'!S331 -> 0 | O7: ='Eig Vec Data Kriteria'!S358 -> 0 | P7: ='Eig Vec Data Kriteria'!S385 -> 0 | Q7: ='Eig Vec Bobot Kriteria'!S7 -> #DIV/0! | R7: =B7*$Q$5+C7*$Q$6+D7*$Q$7+E7*$Q$8+F7*$Q$9+G7*$Q$10+H7*$Q$11+I7*$Q$12+J7*$Q$13+K7*$Q$14+L7*$Q$15+M7*$Q$16+N7*$Q$17+O7*$Q$18+P7*$Q$19 -> #DIV/0!
A8: ='Data Kriteria'!B9 -> 0 | B8: ='Eig Vec Data Kriteria'!S8 -> 0 | C8: ='Eig Vec Data Kriteria'!S35 -> 0 | D8: ='Eig Vec Data Kriteria'!S62 -> 0 | E8: ='Eig Vec Data Kriteria'!S89 -> 0 | F8: ='Eig Vec Data Kriteria'!S116 -> 0 | G8: ='Eig Vec Data Kriteria'!S143 -> 0 | H8: ='Eig Vec Data Kriteria'!S170 -> 0 | I8: ='Eig Vec Data Kriteria'!S197 -> 0 | J8: ='Eig Vec Data Kriteria'!S224 -> 0 | K8: ='Eig Vec Data Kriteria'!S251 -> 0 | L8: ='Eig Vec Data Kriteria'!S278 -> 0 | M8: ='Eig Vec Data Kriteria'!S305 -> 0 | N8: ='Eig Vec Data Kriteria'!S332 -> 0 | O8: ='Eig Vec Data Kriteria'!S359 -> 0 | P8: ='Eig Vec Data Kriteria'!S386 -> 0 | Q8: ='Eig Vec Bobot Kriteria'!S8 -> #DIV/0! | R8: =B8*$Q$5+C8*$Q$6+D8*$Q$7+E8*$Q$8+F8*$Q$9+G8*$Q$10+H8*$Q$11+I8*$Q$12+J8*$Q$13+K8*$Q$14+L8*$Q$15+M8*$Q$16+N8*$Q$17+O8*$Q$18+P8*$Q$19 -> #DIV/0!
A9: ='Data Kriteria'!B10 -> 0 | B9: ='Eig Vec Data Kriteria'!S9 -> 0 | C9: ='Eig Vec Data Kriteria'!S36 -> 0 | D9: ='Eig Vec Data Kriteria'!S63 -> 0 | E9: ='Eig Vec Data Kriteria'!S90 -> 0 | F9: ='Eig Vec Data Kriteria'!S117 -> 0 | G9: ='Eig Vec Data Kriteria'!S144 -> 0 | H9: ='Eig Vec Data Kriteria'!S171 -> 0 | I9: ='Eig Vec Data Kriteria'!S198 -> 0 | J9: ='Eig Vec Data Kriteria'!S225 -> 0 | K9: ='Eig Vec Data Kriteria'!S252 -> 0 | L9: ='Eig Vec Data Kriteria'!S279 -> 0 | M9: ='Eig Vec Data Kriteria'!S306 -> 0 | N9: ='Eig Vec Data Kriteria'!S333 -> 0 | O9: ='Eig Vec Data Kriteria'!S360 -> 0 | P9: ='Eig Vec Data Kriteria'!S387 -> 0 | Q9: ='Eig Vec Bobot Kriteria'!S9 -> #DIV/0! | R9: =B9*$Q$5+C9*$Q$6+D9*$Q$7+E9*$Q$8+F9*$Q$9+G9*$Q$10+H9*$Q$11+I9*$Q$12+J9*$Q$13+K9*$Q$14+L9*$Q$15+M9*$Q$16+N9*$Q$17+O9*$Q$18+P9*$Q$19 -> #DIV/0!
A10: ='Data Kriteria'!B11 -> 0 | B10: ='Eig Vec Data Kriteria'!S10 -> 0 | C10: ='Eig Vec Data Kriteria'!S37 -> 0 | D10: ='Eig Vec Data Kriteria'!S64 -> 0 | E10: ='Eig Vec Data Kriteria'!S91 -> 0 | F10: ='Eig Vec Data Kriteria'!S118 -> 0 | G10: ='Eig Vec Data Kriteria'!S145 -> 0 | H10: ='Eig Vec Data Kriteria'!S172 -> 0 | I10: ='Eig Vec Data Kriteria'!S199 -> 0 | J10: ='Eig Vec Data Kriteria'!S226 -> 0 | K10: ='Eig Vec Data Kriteria'!S253 -> 0 | L10: ='Eig Vec Data Kriteria'!S280 -> 0 | M10: ='Eig Vec Data Kriteria'!S307 -> 0 | N10: ='Eig Vec Data Kriteria'!S334 -> 0 | O10: ='Eig Vec Data Kriteria'!S361 -> 0 | P10: ='Eig Vec Data Kriteria'!S388 -> 0 | Q10: ='Eig Vec Bobot Kriteria'!S10 -> #DIV/0! | R10: =B10*$Q$5+C10*$Q$6+D10*$Q$7+E10*$Q$8+F10*$Q$9+G10*$Q$10+H10*$Q$11+I10*$Q$12+J10*$Q$13+K10*$Q$14+L10*$Q$15+M10*$Q$16+N10*$Q$17+O10*$Q$18+P10*$Q$19 -> #DIV/0!
A11: ='Data Kriteria'!B12 -> 0 | B11: ='Eig Vec Data Kriteria'!S11 -> 0 | C11: ='Eig Vec Data Kriteria'!S38 -> 0 | D11: ='Eig Vec Data Kriteria'!S65 -> 0 | E11: ='Eig Vec Data Kriteria'!S92 -> 0 | F11: ='Eig Vec Data Kriteria'!S119 -> 0 | G11: ='Eig Vec Data Kriteria'!S146 -> 0 | H11: ='Eig Vec Data Kriteria'!S173 -> 0 | I11: ='Eig Vec Data Kriteria'!S200 -> 0 | J11: ='Eig Vec Data Kriteria'!S227 -> 0 | K11: ='Eig Vec Data Kriteria'!S254 -> 0 | L11: ='Eig Vec Data Kriteria'!S281 -> 0 | M11: ='Eig Vec Data Kriteria'!S308 -> 0 | N11: ='Eig Vec Data Kriteria'!S335 -> 0 | O11: ='Eig Vec Data Kriteria'!S362 -> 0 | P11: ='Eig Vec Data Kriteria'!S389 -> 0 | Q11: ='Eig Vec Bobot Kriteria'!S11 -> #DIV/0! | R11: =B11*$Q$5+C11*$Q$6+D11*$Q$7+E11*$Q$8+F11*$Q$9+G11*$Q$10+H11*$Q$11+I11*$Q$12+J11*$Q$13+K11*$Q$14+L11*$Q$15+M11*$Q$16+N11*$Q$17+O11*$Q$18+P11*$Q$19 -> #DIV/0!
A12: ='Data Kriteria'!B13 -> 0 | B12: ='Eig Vec Data Kriteria'!S12 -> 0 | C12: ='Eig Vec Data Kriteria'!S39 -> 0 | D12: ='Eig Vec Data Kriteria'!S66 -> 0 | E12: ='Eig Vec Data Kriteria'!S93 -> 0 | F12: ='Eig Vec Data Kriteria'!S120 -> 0 | G12: ='Eig Vec Data Kriteria'!S147 -> 0 | H12: ='Eig Vec Data Kriteria'!S174 -> 0 | I12: ='Eig Vec Data Kriteria'!S201 -> 0 | J12: ='Eig Vec Data Kriteria'!S228 -> 0 | K12: ='Eig Vec Data Kriteria'!S255 -> 0 | L12: ='Eig Vec Data Kriteria'!S282 -> 0 | M12: ='Eig Vec Data Kriteria'!S309 -> 0 | N12: ='Eig Vec Data Kriteria'!S336 -> 0 | O12: ='Eig Vec Data Kriteria'!S363 -> 0 | P12: ='Eig Vec Data Kriteria'!S390 -> 0 | Q12: ='Eig Vec Bobot Kriteria'!S12 -> #DIV/0! | R12: =B12*$Q$5+C12*$Q$6+D12*$Q$7+E12*$Q$8+F12*$Q$9+G12*$Q$10+H12*$Q$11+I12*$Q$12+J12*$Q$13+K12*$Q$14+L12*$Q$15+M12*$Q$16+N12*$Q$17+O12*$Q$18+P12*$Q$19 -> #DIV/0!
A13: ='Data Kriteria'!B14 -> 0 | B13: ='Eig Vec Data Kriteria'!S13 -> 0 | C13: ='Eig Vec Data Kriteria'!S40 -> 0 | D13: ='Eig Vec Data Kriteria'!S67 -> 0 | E13: ='Eig Vec Data Kriteria'!S94 -> 0 | F13: ='Eig Vec Data Kriteria'!S121 -> 0 | G13: ='Eig Vec Data Kriteria'!S148 -> 0 | H13: ='Eig Vec Data Kriteria'!S175 -> 0 | I13: ='Eig Vec Data Kriteria'!S202 -> 0 | J13: ='Eig Vec Data Kriteria'!S229 -> 0 | K13: ='Eig Vec Data Kriteria'!S256 -> 0 | L13: ='Eig Vec Data Kriteria'!S283 -> 0 | M13: ='Eig Vec Data Kriteria'!S310 -> 0 | N13: ='Eig Vec Data Kriteria'!S337 -> 0 | O13: ='Eig Vec Data Kriteria'!S364 -> 0 | P13: ='Eig Vec Data Kriteria'!S391 -> 0 | Q13: ='Eig Vec Bobot Kriteria'!S13 -> #DIV/0! | R13: =B13*$Q$5+C13*$Q$6+D13*$Q$7+E13*$Q$8+F13*$Q$9+G13*$Q$10+H13*$Q$11+I13*$Q$12+J13*$Q$13+K13*$Q$14+L13*$Q$15+M13*$Q$16+N13*$Q$17+O13*$Q$18+P13*$Q$19 -> #DIV/0!
A14: ='Data Kriteria'!B15 -> 0 | B14: ='Eig Vec Data Kriteria'!S14 -> 0 | C14: ='Eig Vec Data Kriteria'!S41 -> 0 | D14: ='Eig Vec Data Kriteria'!S68 -> 0 | E14: ='Eig Vec Data Kriteria'!S95 -> 0 | F14: ='Eig Vec Data Kriteria'!S122 -> 0 | G14: ='Eig Vec Data Kriteria'!S149 -> 0 | H14: ='Eig Vec Data Kriteria'!S176 -> 0 | I14: ='Eig Vec Data Kriteria'!S203 -> 0 | J14: ='Eig Vec Data Kriteria'!S230 -> 0 | K14: ='Eig Vec Data Kriteria'!S257 -> 0 | L14: ='Eig Vec Data Kriteria'!S284 -> 0 | M14: ='Eig Vec Data Kriteria'!S311 -> 0 | N14: ='Eig Vec Data Kriteria'!S338 -> 0 | O14: ='Eig Vec Data Kriteria'!S365 -> 0 | P14: ='Eig Vec Data Kriteria'!S392 -> 0 | Q14: ='Eig Vec Bobot Kriteria'!S14 -> #DIV/0! | R14: =B14*$Q$5+C14*$Q$6+D14*$Q$7+E14*$Q$8+F14*$Q$9+G14*$Q$10+H14*$Q$11+I14*$Q$12+J14*$Q$13+K14*$Q$14+L14*$Q$15+M14*$Q$16+N14*$Q$17+O14*$Q$18+P14*$Q$19 -> #DIV/0!
A15: ='Data Kriteria'!B16 -> 0 | B15: ='Eig Vec Data Kriteria'!S15 -> 0 | C15: ='Eig Vec Data Kriteria'!S42 -> 0 | D15: ='Eig Vec Data Kriteria'!S69 -> 0 | E15: ='Eig Vec Data Kriteria'!S96 -> 0 | F15: ='Eig Vec Data Kriteria'!S123 -> 0 | G15: ='Eig Vec Data Kriteria'!S150 -> 0 | H15: ='Eig Vec Data Kriteria'!S177 -> 0 | I15: ='Eig Vec Data Kriteria'!S204 -> 0 | J15: ='Eig Vec Data Kriteria'!S231 -> 0 | K15: ='Eig Vec Data Kriteria'!S258 -> 0 | L15: ='Eig Vec Data Kriteria'!S285 -> 0 | M15: ='Eig Vec Data Kriteria'!S312 -> 0 | N15: ='Eig Vec Data Kriteria'!S339 -> 0 | O15: ='Eig Vec Data Kriteria'!S366 -> 0 | P15: ='Eig Vec Data Kriteria'!S393 -> 0 | Q15: ='Eig Vec Bobot Kriteria'!S15 -> #DIV/0! | R15: =B15*$Q$5+C15*$Q$6+D15*$Q$7+E15*$Q$8+F15*$Q$9+G15*$Q$10+H15*$Q$11+I15*$Q$12+J15*$Q$13+K15*$Q$14+L15*$Q$15+M15*$Q$16+N15*$Q$17+O15*$Q$18+P15*$Q$19 -> #DIV/0!
